Workbook

Sheet basic data
N3: checking commodity totals
B4: USE (U) | C4: farms | D4: mines | E4: food manuf. | F4: other manuf. | G4: services | K4: Final Demand | N4: make = use+fd
B5: cattle | C5: 10 | D5: 0 | E5: 80 | F5: 10 | G5: 0 | K5: 0 | N5: =SUM(C19:C23)-SUM(C5:G5,K5) -> 0
B6: iron ore | C6: 0 | D6: 0 | E6: 0 | F6: 100 | G6: 0 | K6: 0 | N6: =SUM(D19:D23)-SUM(C6:G6,K6) -> 0
B7: milk | C7: 10 | D7: 5 | E7: 100 | F7: 0 | G7: 5 | K7: 60 | N7: =SUM(E19:E23)-SUM(C7:G7,K7) -> 0
B8: cheese | C8: 0 | D8: 5 | E8: 0 | F8: 0 | G8: 5 | K8: 200 | N8: =SUM(F19:F23)-SUM(C8:G8,K8) -> 0
B9: fuel | C9: 100 | D9: 200 | E9: 10 | F9: 50 | G9: 50 | K9: 600 | N9: =SUM(G19:G23)-SUM(C9:G9,K9) -> 0
B10: steel | C10: 0 | D10: 5 | E10: 0 | F10: 145 | G10: 0 | K10: 0 | N10: =SUM(H19:H23)-SUM(C10:G10,K10) -> 0
B11: parts | C11: 10 | D11: 5 | E11: 5 | F11: 5 | G11: 10 | K11: 165 | N11: =SUM(I19:I23)-SUM(C11:G11,K11) -> 0
B12: advertising | C12: 5 | D12: 15 | E12: 20 | F12: 40 | G12: 20 | K12: 0 | N12: =SUM(J19:J23)-SUM(C12:G12,K12) -> 0
B14: Primary inputs | C14: 75 | D14: 865 | E14: 65 | F14: 10 | G14: 10
B18: SUPPLY (V) | C18: cattle | D18: iron ore | E18: milk | F18: cheese | G18: fuel | H18: steel | I18: parts | J18: advertising | L18: g
B19: farms | C19: 100 | D19: 0 | E19: 100 | F19: 10 | G19: 0 | H19: 0 | I19: 0 | J19: 0 | L19: =SUM(C19:J19) -> 210
B20: mines | C20: 0 | D20: 100 | E20: 0 | F20: 0 | G20: 1000 | H20: 0 | I20: 0 | J20: 0 | L20: =SUM(C20:J20) -> 1100
B21: food manuf. | C21: 0 | D21: 0 | E21: 80 | F21: 200 | G21: 0 | H21: 0 | I21: 0 | J21: 0 | L21: =SUM(C21:J21) -> 280
B22: other manuf. | C22: 0 | D22: 0 | E22: 0 | F22: 0 | G22: 10 | H22: 150 | I22: 200 | J22: 0 | L22: =SUM(C22:J22) -> 360
B23: services | C23: 0 | D23: 0 | E23: 0 | F23: 0 | G23: 0 | H23: 0 | I23: 0 | J23: 100 | L23: =SUM(C23:J23) -> 100
B27: q | C27: =SUM(C19:C23) -> 100 | D27: =SUM(D19:D23) -> 100 | E27: =SUM(E19:E23) -> 180 | F27: =SUM(F19:F23) -> 210 | G27: =SUM(G19:G23) -> 1010 | H27: =SUM(H19:H23) -> 150 | I27: =SUM(I19:I23) -> 200 | J27: =SUM(J19:J23) -> 100

Sheet Model derivation
B1: g' | C1: 210 | D1: 1100 | E1: 280 | F1: 360 | G1: 100
B3: B (U/g) | C3: farms | D3: mines | E3: food manuf. | F3: other manuf. | G3: services
B4: cattle | C4: ='basic data'!C5/'Model derivation'!C$1 -> 0.047619048 | D4: ='basic data'!D5/'Model derivation'!D$1 -> 0 | E4: ='basic data'!E5/'Model derivation'!E$1 -> 0.28571429 | F4: ='basic data'!F5/'Model derivation'!F$1 -> 0.027777778 | G4: ='basic data'!G5/'Model derivation'!G$1 -> 0
B5: iron ore | C5: ='basic data'!C6/'Model derivation'!C$1 -> 0 | D5: ='basic data'!D6/'Model derivation'!D$1 -> 0 | E5: ='basic data'!E6/'Model derivation'!E$1 -> 0 | F5: ='basic data'!F6/'Model derivation'!F$1 -> 0.27777778 | G5: ='basic data'!G6/'Model derivation'!G$1 -> 0
B6: milk | C6: ='basic data'!C7/'Model derivation'!C$1 -> 0.047619048 | D6: ='basic data'!D7/'Model derivation'!D$1 -> 0.0045454545 | E6: ='basic data'!E7/'Model derivation'!E$1 -> 0.35714286 | F6: ='basic data'!F7/'Model derivation'!F$1 -> 0 | G6: ='basic data'!G7/'Model derivation'!G$1 -> 0.05
B7: cheese | C7: ='basic data'!C8/'Model derivation'!C$1 -> 0 | D7: ='basic data'!D8/'Model derivation'!D$1 -> 0.0045454545 | E7: ='basic data'!E8/'Model derivation'!E$1 -> 0 | F7: ='basic data'!F8/'Model derivation'!F$1 -> 0 | G7: ='basic data'!G8/'Model derivation'!G$1 -> 0.05
B8: fuel | C8: ='basic data'!C9/'Model derivation'!C$1 -> 0.47619048 | D8: ='basic data'!D9/'Model derivation'!D$1 -> 0.18181818 | E8: ='basic data'!E9/'Model derivation'!E$1 -> 0.035714286 | F8: ='basic data'!F9/'Model derivation'!F$1 -> 0.13888889 | G8: ='basic data'!G9/'Model derivation'!G$1 -> 0.5
B9: steel | C9: ='basic data'!C10/'Model derivation'!C$1 -> 0 | D9: ='basic data'!D10/'Model derivation'!D$1 -> 0.0045454545 | E9: ='basic data'!E10/'Model derivation'!E$1 -> 0 | F9: ='basic data'!F10/'Model derivation'!F$1 -> 0.40277778 | G9: ='basic data'!G10/'Model derivation'!G$1 -> 0
B10: parts | C10: ='basic data'!C11/'Model derivation'!C$1 -> 0.047619048 | D10: ='basic data'!D11/'Model derivation'!D$1 -> 0.0045454545 | E10: ='basic data'!E11/'Model derivation'!E$1 -> 0.017857143 | F10: ='basic data'!F11/'Model derivation'!F$1 -> 0.013888889 | G10: ='basic data'!G11/'Model derivation'!G$1 -> 0.1
B11: advertising | C11: ='basic data'!C12/'Model derivation'!C$1 -> 0.023809524 | D11: ='basic data'!D12/'Model derivation'!D$1 -> 0.013636364 | E11: ='basic data'!E12/'Model derivation'!E$1 -> 0.071428571 | F11: ='basic data'!F12/'Model derivation'!F$1 -> 0.11111111 | G11: ='basic data'!G12/'Model derivation'!G$1 -> 0.2
B13: Σ | C13: =SUM(C4:C11) -> 0.64285714 | D13: =SUM(D4:D11) -> 0.21363636 | E13: =SUM(E4:E11) -> 0.76785714 | F13: =SUM(F4:F11) -> 0.97222222 | G13: =SUM(G4:G11) -> 0.9
B15: D (V/q) | C15: cattle | D15: iron ore | E15: milk | F15: cheese | G15: fuel | H15: steel | I15: parts | J15: advertising
B16: farms | C16: ='basic data'!C19/'basic data'!C$27 -> 1 | D16: ='basic data'!D19/'basic data'!D$27 -> 0 | E16: ='basic data'!E19/'basic data'!E$27 -> 0.55555556 | F16: ='basic data'!F19/'basic data'!F$27 -> 0.047619048 | G16: ='basic data'!G19/'basic data'!G$27 -> 0 | H16: ='basic data'!H19/'basic data'!H$27 -> 0 | I16: ='basic data'!I19/'basic data'!I$27 -> 0 | J16: ='basic data'!J19/'basic data'!J$27 -> 0
B17: mines | C17: ='basic data'!C20/'basic data'!C$27 -> 0 | D17: ='basic data'!D20/'basic data'!D$27 -> 1 | E17: ='basic data'!E20/'basic data'!E$27 -> 0 | F17: ='basic data'!F20/'basic data'!F$27 -> 0 | G17: ='basic data'!G20/'basic data'!G$27 -> 0.99009901 | H17: ='basic data'!H20/'basic data'!H$27 -> 0 | I17: ='basic data'!I20/'basic data'!I$27 -> 0 | J17: ='basic data'!J20/'basic data'!J$27 -> 0
B18: food manuf. | C18: ='basic data'!C21/'basic data'!C$27 -> 0 | D18: ='basic data'!D21/'basic data'!D$27 -> 0 | E18: ='basic data'!E21/'basic data'!E$27 -> 0.44444444 | F18: ='basic data'!F21/'basic data'!F$27 -> 0.95238095 | G18: ='basic data'!G21/'basic data'!G$27 -> 0 | H18: ='basic data'!H21/'basic data'!H$27 -> 0 | I18: ='basic data'!I21/'basic data'!I$27 -> 0 | J18: ='basic data'!J21/'basic data'!J$27 -> 0
B19: other manuf. | C19: ='basic data'!C22/'basic data'!C$27 -> 0 | D19: ='basic data'!D22/'basic data'!D$27 -> 0 | E19: ='basic data'!E22/'basic data'!E$27 -> 0 | F19: ='basic data'!F22/'basic data'!F$27 -> 0 | G19: ='basic data'!G22/'basic data'!G$27 -> 0.0099009901 | H19: ='basic data'!H22/'basic data'!H$27 -> 1 | I19: ='basic data'!I22/'basic data'!I$27 -> 1 | J19: ='basic data'!J22/'basic data'!J$27 -> 0
B20: services | C20: ='basic data'!C23/'basic data'!C$27 -> 0 | D20: ='basic data'!D23/'basic data'!D$27 -> 0 | E20: ='basic data'!E23/'basic data'!E$27 -> 0 | F20: ='basic data'!F23/'basic data'!F$27 -> 0 | G20: ='basic data'!G23/'basic data'!G$27 -> 0 | H20: ='basic data'!H23/'basic data'!H$27 -> 0 | I20: ='basic data'!I23/'basic data'!I$27 -> 0 | J20: ='basic data'!J23/'basic data'!J$27 -> 1
B22: Σ | C22: =SUM(C16:C20) -> 1 | D22: =SUM(D16:D20) -> 1 | E22: =SUM(E16:E20) -> 1 | F22: =SUM(F16:F20) -> 1 | G22: =SUM(G16:G20) -> 1 | H22: =SUM(H16:H20) -> 1 | I22: =SUM(I16:I20) -> 1 | J22: =SUM(J16:J20) -> 1
B24: DB | C24: farms | D24: mines | E24: food manuf. | F24: other manuf. | G24: services | J24: I | K24: farms | L24: mines | M24: food manuf. | N24: other manuf. | O24: services
B25: farms | C25: {=MMULT($C$16:$J$20,$C$4:$G$11)} -> 0.074074074 | D25: 0.0027417027 | E25: 0.48412698 | F25: 0.027777778 | G25: 0.03015873 | J25: farms | K25: 1 | L25: 0 | M25: 0 | N25: 0 | O25: 0
B26: mines | C26: 0.47147572 | D26: 0.180018 | E26: 0.035360679 | F26: 0.41529153 | G26: 0.4950495 | J26: mines | K26: 0 | L26: 1 | M26: 0 | N26: 0 | O26: 0
B27: food manuf. | C27: 0.021164021 | D27: 0.0063492063 | E27: 0.15873016 | F27: 0 | G27: 0.06984127 | J27: food manuf. | K27: 0 | L27: 0 | M27: 1 | N27: 0 | O27: 0
B28: other manuf. | C28: 0.052333805 | D28: 0.010891089 | E28: 0.01821075 | F28: 0.4180418 | G28: 0.1049505 | J28: other manuf. | K28: 0 | L28: 0 | M28: 0 | N28: 1 | O28: 0
B29: services | C29: 0.023809524 | D29: 0.013636364 | E29: 0.071428571 | F29: 0.11111111 | G29: 0.2 | J29: services | K29: 0 | L29: 0 | M29: 0 | N29: 0 | O29: 1
B31: (I-DB) | C31: farms | D31: mines | E31: food manuf. | F31: other manuf. | G31: services | I31: De | K31: output to final demand
B32: farms | C32: =K25-C25 -> 0.92592593 | D32: =L25-D25 -> -0.0027417027 | E32: =M25-E25 -> -0.48412698 | F32: =N25-F25 -> -0.027777778 | G32: =O25-G25 -> -0.03015873 | J32: {=MMULT($C$16:$J$20,'basic data'!$K$5:$K$12)} -> 42.857143
B33: mines | C33: =K26-C26 -> -0.47147572 | D33: =L26-D26 -> 0.819982 | E33: =M26-E26 -> -0.035360679 | F33: =N26-F26 -> -0.41529153 | G33: =O26-G26 -> -0.4950495 | J33: 594.05941
B34: food manuf. | C34: =K27-C27 -> -0.021164021 | D34: =L27-D27 -> -0.0063492063 | E34: =M27-E27 -> 0.84126984 | F34: =N27-F27 -> 0 | G34: =O27-G27 -> -0.06984127 | J34: 217.14286
B35: other manuf. | C35: =K28-C28 -> -0.052333805 | D35: =L28-D28 -> -0.010891089 | E35: =M28-E28 -> -0.01821075 | F35: =N28-F28 -> 0.5819582 | G35: =O28-G28 -> -0.1049505 | J35: 170.94059
B36: services | C36: =K29-C29 -> -0.023809524 | D36: =L29-D29 -> -0.013636364 | E36: =M29-E29 -> -0.071428571 | F36: =N29-F29 -> -0.11111111 | G36: =O29-G29 -> 0.8 | J36: 0
B40: (I-DB)ˉ¹ | C40: farms | D40: mines | E40: food manuf. | F40: other manuf. | G40: services | I40: g calc | J40: g=(I-DB)ˉ¹De | L40: real g | M40: g
B41: farms | C41: {=MINVERSE($C$32:$G$36)} -> 1.1085988 | D41: 0.011794948 | E41: 0.6501927 | F41: 0.08363738 | G41: 0.11682635 | J41: {=MMULT($C$41:$G$45,$J$32:$J$36)} -> 210 | M41: ='basic data'!L19 -> 210
B42: mines | C42: 0.7436833 | D42: 1.2582753 | E42: 0.59062483 | F42: 1.1254649 | G42: 1.0058815 | J42: 1100 | M42: ='basic data'!L20 -> 1100
B43: food manuf. | C43: 0.039045837 | D43: 0.012036363 | E43: 1.2225685 | F43: 0.033369898 | G43: 0.12003012 | J43: 280 | M43: ='basic data'!L21 -> 280
B44: other manuf. | C44: 0.1268754 | D44: 0.029858289 | E44: 0.13618195 | F44: 1.7974311 | G44: 0.27095018 | J44: 360 | M44: ='basic data'!L22 -> 360
B45: services | C45: 0.06677825 | D45: 0.027020574 | E45: 0.15749051 | F45: 0.27429594 | G45: 1.3189716 | J45: 100 | M45: ='basic data'!L23 -> 100
B47: meaning? | C47: dollars of output from industry at row to deliver (to final demand) a dollar of output from industry at column
B50: decompostion of row one of (I-DB)ˉ¹ times column one of De (Row 1 of (I-DB)ˉ¹ times column of De)
B52: 1.11 * 42.86 ($1.11 of production from farms is required to deliver a dollar of production from farms, so to get 42.86 of final demand we need farms to produce:) | R52: =C41*J32 -> 47.511377
A53: plus | B53: 0.01 * 594.06 ($0.01 of production from farms is required to deliver a dollar of production from mines, so to get 594.06 of final demand we need farms to produce:) | R53: =D41*J33 -> 7.0068996
...

Sheet Indicator calculations
B2: Intensity indicators
C4: emissions per unit of output (direct emissions intensity)
C5: a | D5: farms | E5: mines | F5: food manuf. | G5: other manuf. | H5: services | J5: (I-DB)ˉ¹ | K5: farms | L5: mines | M5: food manuf. | N5: other manuf. | O5: services
C6: co2/g | D6: 0.5 | E6: 0.8 | F6: 0.3 | G6: 0.4 | H6: 0.1 | J6: farms | K6: 1.1085988 | L6: 0.011794948 | M6: 0.6501927 | N6: 0.08363738 | O6: 0.11682635
J7: mines | K7: 0.7436833 | L7: 1.2582753 | M7: 0.59062483 | N7: 1.1254649 | O7: 1.0058815
J8: food manuf. | K8: 0.039045837 | L8: 0.012036363 | M8: 1.2225685 | N8: 0.033369898 | O8: 0.12003012
C9: alpha inverse | J9: other manuf. | K9: 0.1268754 | L9: 0.029858289 | M9: 0.13618195 | N9: 1.7974311 | O9: 0.27095018
D10: {=MMULT($D$6:$H$6,$K$6:$O$10)} -> 1.2183878 | E10: 1.030774 | F10: 1.2345886 | G10: 1.6986036 | H10: 1.1394046 | J10: services | K10: 0.06677825 | L10: 0.027020574 | M10: 0.15749051 | N10: 0.27429594 | O10: 1.3189716
C12: So, a*(I-DB)ˉ¹ for row of a times column 1 of (I-DB)ˉ¹ is...
C14: 0.5 * 1.11 (1.11 dollars of production from farms is required to deliver a dollar of production from farms. Farms emit .05 CO2 per dollar of output,so in terms of emissions this is:) | S14: =D6*'Model derivation'!C41 -> 0.5542994
B15: plus | C15: 0.8 * 0.74 (0.74 dollars of production from mines is required to deliver a dollar of production from farms. Mines emit .8 CO2 per dollar of output, so in terms of emissions this is:) | S15: =E6*'Model derivation'!C42 -> 0.59494664
B16: plus | C16: 0.3 * 0.04 (0.04 dollars of production from food manuf. Is required to deliver a dollar of production from farms. Food manuf. Emit .3 CO2 per dollar of output, so in terms of emissions:) | S16: ='Model derivation'!C43*F6 -> 0.011713751
B17: plus | C17: 0.4 * 0.13 (0.13 dollars of production from other manuf. Is required to deliver a dollar of output from farms. Other manuf. Emit .4 CO2 per dollar of output, so in terms of emissions:) | S17: =G6*'Model derivation'!C44 -> 0.05075016
B18: plus | C18: 0.1 * 0.01 (0.01 dollars of production from services is required to deliver a dollar of output from farms. Services emit .1 CO2 per dollar of output, so in terms of emissions this is:) | S18: =H6*'Model derivation'!C45 -> 0.006677825
R19: SUM | S19: =SUM(S14:S18) -> 1.2183878
C20: This is the total emissions required (direct plus indirect) from all industries per dollar of output from farms.
