Workbook

Sheet Matrix Algebra
A2: Matrices | C2: M = | D2: 2 | E2: 1 | F2: 3
D3: 4 | E3: 6 | F3: 12
C5: N = | D5: 1 | E5: 2 | F5: 3
D6: 3 | E6: 2 | F6: 1
A8: Adición | C8: M + N = | D8: {=M+N} -> 3 | E8: 3 | F8: 6
D9: 7 | E9: 8 | F9: 13
A11: Adición no posible | C11: O = | D11: 2 | E11: 2
D12: 3 | E12: 4
C14: M + O = | D14: {=M+O} -> 4 | E14: 3 | F14: #N/A
D15: 7 | E15: 10 | F15: #N/A
A17: Igualdad | C17: M = N | D17: {=M=N} -> 0 | E17: 0 | F17: 1 | H17: {=M=N} -> 0 | I17: 0 | J17: 1
D18: 0 | E18: 0 | F18: 0 | H18: 0 | I18: 0 | J18: 0
A20: Resta | C20: D = M - N = | D20: {=M-N} -> 1 | E20: -1 | F20: 0
D21: 1 | E21: 4 | F21: 11
A23: Matriz nula | C23: ZETA = | D23: 0 | E23: 0 | F23: 0
D24: 0 | E24: 0 | F24: 0
C26: M + ZETA = | D26: {=M + ZETA} -> 2 | E26: 1 | F26: 3
D27: 4 | E27: 6 | F27: 12
A29: Multiplicación por un escalar | C29: M * 2 = | D29: {=M*2} -> 4 | E29: 2 | F29: 6 | H29: {=M*2} -> 4 | I29: 2 | J29: 6
D30: 8 | E30: 12 | F30: 24 | H30: 8 | I30: 12 | J30: 24
A32: Multiplicación de matrices | C32: Q = | D32: 2 | E32: 0 | F32: 4
D33: 1 | E33: 1 | F33: 2 | H33: {=MMULT(M,Q)} -> 14 | I33: 13 | J33: 25
D34: 3 | E34: 4 | F34: 5 | H34: 50 | I34: 54 | J34: 88
C36: M * Q = | D36: {=MMULT(M,Q)} -> 14 | E36: 13 | F36: 25
D37: 50 | E37: 54 | F37: 88
A39: Multiplicación no posible | C39: Q * M = | D39: =MMULT(Q,M) -> #VALUE! | E39: =#VALUE! -> #VALUE! | F39: =#VALUE! -> #VALUE!
D40: =#VALUE! -> #VALUE! | E40: =#VALUE! -> #VALUE! | F40: =#VALUE! -> #VALUE!
D41: =#VALUE! -> #VALUE! | E41: =#VALUE! -> #VALUE! | F41: =#VALUE! -> #VALUE!
A43: Matriz identidad incorrecta | C43: TM = | D43: 1 | E43: 1 | F43: 1
D44: 1 | E44: 1 | F44: 1
D45: 1 | E45: 1 | F45: 1
C47: M * TM = | D47: {=MMULT(M,TM)} -> 6 | E47: 6 | F47: 6
D48: 22 | E48: 22 | F48: 22
A50: Matriz identidad para posmultiplicación | C50: I = | D50: {=_xlfn.MUNIT(3)} -> 1 | E50: 0 | F50: 0
D51: 0 | E51: 1 | F51: 0
D52: 0 | E52: 0 | F52: 1
C54: M * I = | D54: {=MMULT(M,I)} -> 2 | E54: 1 | F54: 3
D55: 4 | E55: 6 | F55: 12
A57: Matriz identidad para premultiplicación | C57: IP = | D57: {=_xlfn.MUNIT(2)} -> 1 | E57: 0
D58: 0 | E58: 1
...

Sheet Input-Output Model
C3: Agriculture | D3: Manufacturing | E3: Final demand | G3: Total Output (x)
B4: Agriculture | C4: 150 | D4: 500 | E4: 350 | G4: =SUM(C4:E4) -> 1000
B5: Manufacturing | C5: 200 | D5: 100 | E5: 1700 | G5: =SUM(C5:E5) -> 2000
B7: Payments | C7: 650 | D7: 1400 | E7: 1100
B8: Total outlays | C8: 1000 | D8: 2000 | E8: 3150
B12: xhat | C12: {=IF(G4:G5=TRANSPOSE(G4:G5),G4:G5,0)} -> 1000 | D12: 0
C13: 0 | D13: 2000
B15: xhat ^-1 | C15: {=MINVERSE(xhat)} -> 0.001 | D15: 0
C16: 0 | D16: 0.0005
B18: A = Z * xhat ^-1 = | C18: {=MMULT(Z,xhatinv)} -> 0.15 | D18: 0.25
C19: 0.2 | D19: 0.05
B21: Identity matrix | C21: {=_xlfn.MUNIT(2)} -> 1 | D21: 0
C22: 0 | D22: 1
B24: Leontief = L = | C24: {=MINVERSE((identity-REQ))} -> 1.2541254 | D24: 0.330033
C25: 0.2640264 | D25: 1.1221122
B27: Model Calibration | C27: {=MMULT(L,fdem)} -> 1000
C28: 2000
B30: New Demand | C30: 600
C31: 1500
B33: L * Fnew = Xnew | C33: {=MMULT(L,fdemnew)} -> 1247.5248
C34: 1841.5842
B36: Xnew diag | C36: {=IF(C33:C34=TRANSPOSE(C33:C34),C33:C34,0)} -> 1247.5248 | D36: 0
C37: 0 | D37: 1841.5842
B39: A * xnew diag = | C39: {=MMULT(REQ,xnewdiag)} -> 187.12871 | D39: 460.39604
C40: 249.50495 | D40: 92.079208
B42: New table
C44: Agriculture | D44: Manufacturing | E44: Final demand | G44: Total Output (x)
B45: Agriculture | C45: {=C39:D40} -> 187.12871 | D45: 460.39604 | E45: {=C30:C31} -> 600 | G45: =SUM(C45:E45) -> 1247.5248
B46: Manufacturing | C46: 249.50495 | D46: 92.079208 | E46: 1500 | G46: =SUM(C46:E46) -> 1841.5842
B48: Payments | C48: =C49-SUM(C45:C46) -> 810.89109 | D48: =D49-SUM(D45:D46) -> 1289.1089 | E48: 1100
B49: Total outlays | C49: =G45 -> 1247.5248 | D49: =G46 -> 1841.5842 | E49: 3200

Sheet Tool
A1: The World Bank
A2: Kyrgyz Republic
A3: Rapid Environmentally Extended Input-Output Analysis Tool
A4: (current prices, $ million)
D5: Initial setup | H5: Output | L5: Employment | P5: Modeled regional employment | Z5: Modeled Environmental Factors
D6: Total Initial Final Demand | E6: Changes in final demand per sector | F6: New final demand | H6: Initial Output | I6: New Output | J6: Changes in Output | L6: Initial Employment | M6: Total Modeled employment | N6: Changes in Employment | P6: Batken oblast | Q6: Djalal-Abad | R6: Issyk-Kul | S6: Naryn oblast | T6: Osh oblast | U6: Talas oblast | V6: Chui oblast | W6: Bishkek city | X6: Osh city | Z6: Energy Usage (TJ) | AA6: Total CO2 emissions (Gg) | AB6: WFN: Total water footprint (Mm3/yr) - Blue | AC6: WFN: Total water footprint (Mm3/yr) - Green | AD6: WFN: Total water footprint (Mm3/yr) - Grey
A8: Agriculture, hunting, forestry, and fishing | B8: c1 | D8: 1483.3513 | E8: 0 | F8: =D8*(1+E8) -> 1483.3513 | H8: 3054.468 | I8: {=MMULT(KYZ_EEIO_2017!$D$265:$AK$298,Tool!F8:F41)} -> 3054.468 | J8: =IF(H8=0,0,(I8-H8)/H8) -> 0 | L8: 541400 | M8: =SUM(P8:X8) -> 541400 | N8: =M8-L8 -> 0 | P8: =$I8*KYZ_EEIO_2017!CD8 -> 52400 | Q8: =$I8*KYZ_EEIO_2017!CE8 -> 125200 | R8: =$I8*KYZ_EEIO_2017!CF8 -> 42300 | S8: =$I8*KYZ_EEIO_2017!CG8 -> 41000 | T8: =$I8*KYZ_EEIO_2017!CH8 -> 175600 | U8: =$I8*KYZ_EEIO_2017!CI8 -> 58400 | V8: =$I8*KYZ_EEIO_2017!CJ8 -> 42100 | W8: =$I8*KYZ_EEIO_2017!CK8 -> 3200 | X8: =$I8*KYZ_EEIO_2017!CL8 -> 1200 | Z8: =$I8*KYZ_EEIO_2017!CY8 -> 1912.0999 | AA8: =$I8*KYZ_EEIO_2017!CZ8 -> 1350.7742 | AB8: =$I8*KYZ_EEIO_2017!DA8 -> 7117.8215 | AC8: =$I8*KYZ_EEIO_2017!DB8 -> 11933.122 | AD8: =$I8*KYZ_EEIO_2017!DC8 -> 432.85533
A9: Mining and quarrying | B9: c2 | D9: 53.702231 | E9: 0 | F9: =D9*(1+E9) -> 53.702231 | H9: 145.42287 | I9: 145.42287 | J9: =IF(H9=0,0,(I9-H9)/H9) -> 0 | L9: 12700 | M9: =SUM(P9:X9) -> 12700 | N9: =M9-L9 -> 0 | P9: =$I9*KYZ_EEIO_2017!CD9 -> 4200 | Q9: =$I9*KYZ_EEIO_2017!CE9 -> 1400 | R9: =$I9*KYZ_EEIO_2017!CF9 -> 2100 | S9: =$I9*KYZ_EEIO_2017!CG9 -> 3300 | T9: =$I9*KYZ_EEIO_2017!CH9 -> 0 | U9: =$I9*KYZ_EEIO_2017!CI9 -> 100 | V9: =$I9*KYZ_EEIO_2017!CJ9 -> 1600 | W9: =$I9*KYZ_EEIO_2017!CK9 -> 0 | X9: =$I9*KYZ_EEIO_2017!CL9 -> 0 | Z9: =$I9*KYZ_EEIO_2017!CY9 -> 147.72395 | AA9: =$I9*KYZ_EEIO_2017!CZ9 -> 181.80787 | AB9: =$I9*KYZ_EEIO_2017!DA9 -> 0.22026195 | AC9: =$I9*KYZ_EEIO_2017!DB9 -> 0 | AD9: =$I9*KYZ_EEIO_2017!DC9 -> 3.055247
A10: Food, beverages, and tobacco | B10: c3 | D10: 389.24916 | E10: 0 | F10: =D10*(1+E10) -> 389.24916 | H10: 643.01735 | I10: 643.01735 | J10: =IF(H10=0,0,(I10-H10)/H10) -> 0 | L10: 37064.291 | M10: =SUM(P10:X10) -> 37064.291 | N10: =M10-L10 -> 0 | P10: =$I10*KYZ_EEIO_2017!CD10 -> 1314.7806 | Q10: =$I10*KYZ_EEIO_2017!CE10 -> 5306.0789 | R10: =$I10*KYZ_EEIO_2017!CF10 -> 1596.5193 | S10: =$I10*KYZ_EEIO_2017!CG10 -> 313.043 | T10: =$I10*KYZ_EEIO_2017!CH10 -> 3928.6897 | U10: =$I10*KYZ_EEIO_2017!CI10 -> 626.086 | V10: =$I10*KYZ_EEIO_2017!CJ10 -> 11269.548 | W10: =$I10*KYZ_EEIO_2017!CK10 -> 11504.33 | X10: =$I10*KYZ_EEIO_2017!CL10 -> 1205.2156 | Z10: =$I10*KYZ_EEIO_2017!CY10 -> 736.61604 | AA10: =$I10*KYZ_EEIO_2017!CZ10 -> 280.60886 | AB10: =$I10*KYZ_EEIO_2017!DA10 -> 1.187814 | AC10: =$I10*KYZ_EEIO_2017!DB10 -> 0 | AD10: =$I10*KYZ_EEIO_2017!DC10 -> 16.476134
A11: Textiles and textile products | B11: c4 | D11: 118.23605 | E11: 0 | F11: =D11*(1+E11) -> 118.23605 | H11: 128.31083 | I11: 128.31083 | J11: =IF(H11=0,0,(I11-H11)/H11) -> 0 | L11: 8792.7829 | M11: =SUM(P11:X11) -> 8792.7829 | N11: =M11-L11 -> 0 | P11: =$I11*KYZ_EEIO_2017!CD11 -> 311.90615 | Q11: =$I11*KYZ_EEIO_2017!CE11 -> 1258.7641 | R11: =$I11*KYZ_EEIO_2017!CF11 -> 378.74318 | S11: =$I11*KYZ_EEIO_2017!CG11 -> 74.263369 | T11: =$I11*KYZ_EEIO_2017!CH11 -> 932.00528 | U11: =$I11*KYZ_EEIO_2017!CI11 -> 148.52674 | V11: =$I11*KYZ_EEIO_2017!CJ11 -> 2673.4813 | W11: =$I11*KYZ_EEIO_2017!CK11 -> 2729.1788 | X11: =$I11*KYZ_EEIO_2017!CL11 -> 285.91397 | Z11: =$I11*KYZ_EEIO_2017!CY11 -> 257.57702 | AA11: =$I11*KYZ_EEIO_2017!CZ11 -> 63.024613 | AB11: =$I11*KYZ_EEIO_2017!DA11 -> 0.48447421 | AC11: =$I11*KYZ_EEIO_2017!DB11 -> 0 | AD11: =$I11*KYZ_EEIO_2017!DC11 -> 6.7201275
A12: Leather, leather products, and footwear | B12: c5 | D12: 12.504728 | E12: 0 | F12: =D12*(1+E12) -> 12.504728 | H12: 13.595506 | I12: 13.595506 | J12: =IF(H12=0,0,(I12-H12)/H12) -> -4.1810449e-15 | L12: 931.66201 | M12: =SUM(P12:X12) -> 931.66201 | N12: =M12-L12 -> 0 | P12: =$I12*KYZ_EEIO_2017!CD12 -> 33.048821 | Q12: =$I12*KYZ_EEIO_2017!CE12 -> 133.3756 | R12: =$I12*KYZ_EEIO_2017!CF12 -> 40.130712 | S12: =$I12*KYZ_EEIO_2017!CG12 -> 7.868767 | T12: =$I12*KYZ_EEIO_2017!CH12 -> 98.753026 | U12: =$I12*KYZ_EEIO_2017!CI12 -> 15.737534 | V12: =$I12*KYZ_EEIO_2017!CJ12 -> 283.27561 | W12: =$I12*KYZ_EEIO_2017!CK12 -> 289.17719 | X12: =$I12*KYZ_EEIO_2017!CL12 -> 30.294753 | Z12: =$I12*KYZ_EEIO_2017!CY12 -> 33.107265 | AA12: =$I12*KYZ_EEIO_2017!CZ12 -> 6.1392604 | AB12: =$I12*KYZ_EEIO_2017!DA12 -> 0.065430241 | AC12: =$I12*KYZ_EEIO_2017!DB12 -> 0 | AD12: =$I12*KYZ_EEIO_2017!DC12 -> 0.90758096
A13: Wood and products of wood and cork | B13: c6 | D13: 2.8206512 | E13: 0 | F13: =D13*(1+E13) -> 2.8206512 | H13: 3.9497932 | I13: 3.9497932 | J13: =IF(H13=0,0,(I13-H13)/H13) -> 0 | L13: 358.07881 | M13: =SUM(P13:X13) -> 358.07881 | N13: =M13-L13 -> 0 | P13: =$I13*KYZ_EEIO_2017!CD13 -> 12.70212 | Q13: =$I13*KYZ_EEIO_2017!CE13 -> 51.262127 | R13: =$I13*KYZ_EEIO_2017!CF13 -> 15.424003 | S13: =$I13*KYZ_EEIO_2017!CG13 -> 3.0243143 | T13: =$I13*KYZ_EEIO_2017!CH13 -> 37.955145 | U13: =$I13*KYZ_EEIO_2017!CI13 -> 6.0486286 | V13: =$I13*KYZ_EEIO_2017!CJ13 -> 108.87531 | W13: =$I13*KYZ_EEIO_2017!CK13 -> 111.14355 | X13: =$I13*KYZ_EEIO_2017!CL13 -> 11.64361 | Z13: =$I13*KYZ_EEIO_2017!CY13 -> 22.713789 | AA13: =$I13*KYZ_EEIO_2017!CZ13 -> 1.7543551 | AB13: =$I13*KYZ_EEIO_2017!DA13 -> 0.049561495 | AC13: =$I13*KYZ_EEIO_2017!DB13 -> 0 | AD13: =$I13*KYZ_EEIO_2017!DC13 -> 0.68746605
A14: Pulp, paper, paper products, printing, and publishing | B14: c7 | D14: 26.361181 | E14: 0 | F14: =D14*(1+E14) -> 26.361181 | H14: 39.479936 | I14: 39.479936 | J14: =IF(H14=0,0,(I14-H14)/H14) -> 0 | L14: 2820.6013 | M14: =SUM(P14:X14) -> 2820.6013 | N14: =M14-L14 -> 0 | P14: =$I14*KYZ_EEIO_2017!CD14 -> 100.05511 | Q14: =$I14*KYZ_EEIO_2017!CE14 -> 403.79385 | R14: =$I14*KYZ_EEIO_2017!CF14 -> 121.49549 | S14: =$I14*KYZ_EEIO_2017!CG14 -> 23.822646 | T14: =$I14*KYZ_EEIO_2017!CH14 -> 298.97421 | U14: =$I14*KYZ_EEIO_2017!CI14 -> 47.645292 | V14: =$I14*KYZ_EEIO_2017!CJ14 -> 857.61526 | W14: =$I14*KYZ_EEIO_2017!CK14 -> 875.48224 | X14: =$I14*KYZ_EEIO_2017!CL14 -> 91.717187 | Z14: =$I14*KYZ_EEIO_2017!CY14 -> 78.993743 | AA14: =$I14*KYZ_EEIO_2017!CZ14 -> 17.757572 | AB14: =$I14*KYZ_EEIO_2017!DA14 -> 0.15893346 | AC14: =$I14*KYZ_EEIO_2017!DB14 -> 0 | AD14: =$I14*KYZ_EEIO_2017!DC14 -> 2.2045613
A15: Coke, refined petroleum, and nuclear fuel | B15: c8 | D15: 49.222067 | E15: 0 | F15: =D15*(1+E15) -> 49.222067 | H15: 84.707159 | I15: 84.707159 | J15: =IF(H15=0,0,(I15-H15)/H15) -> 0 | L15: 6285.5449 | M15: =SUM(P15:X15) -> 6285.5449 | N15: =M15-L15 -> 0 | P15: =$I15*KYZ_EEIO_2017!CD15 -> 222.96696 | Q15: =$I15*KYZ_EEIO_2017!CE15 -> 899.83096 | R15: =$I15*KYZ_EEIO_2017!CF15 -> 270.7456 | S15: =$I15*KYZ_EEIO_2017!CG15 -> 53.087372 | T15: =$I15*KYZ_EEIO_2017!CH15 -> 666.24652 | U15: =$I15*KYZ_EEIO_2017!CI15 -> 106.17474 | V15: =$I15*KYZ_EEIO_2017!CJ15 -> 1911.1454 | W15: =$I15*KYZ_EEIO_2017!CK15 -> 1950.9609 | X15: =$I15*KYZ_EEIO_2017!CL15 -> 204.38638 | Z15: =$I15*KYZ_EEIO_2017!CY15 -> 8207.6301 | AA15: =$I15*KYZ_EEIO_2017!CZ15 -> 93.403021 | AB15: =$I15*KYZ_EEIO_2017!DA15 -> 0.11881106 | AC15: =$I15*KYZ_EEIO_2017!DB15 -> 0 | AD15: =$I15*KYZ_EEIO_2017!DC15 -> 1.6480247
A16: Chemicals and chemical products | B16: c9 | D16: 22.504599 | E16: 0 | F16: =D16*(1+E16) -> 22.504599 | H16: 39.147976 | I16: 39.147976 | J16: =IF(H16=0,0,(I16-H16)/H16) -> 0 | L16: 2906.5273 | M16: =SUM(P16:X16) -> 2906.5273 | N16: =M16-L16 -> 0 | P16: =$I16*KYZ_EEIO_2017!CD16 -> 103.10316 | Q16: =$I16*KYZ_EEIO_2017!CE16 -> 416.09491 | R16: =$I16*KYZ_EEIO_2017!CF16 -> 125.1967 | S16: =$I16*KYZ_EEIO_2017!CG16 -> 24.548372 | T16: =$I16*KYZ_EEIO_2017!CH16 -> 308.08207 | U16: =$I16*KYZ_EEIO_2017!CI16 -> 49.096745 | V16: =$I16*KYZ_EEIO_2017!CJ16 -> 883.74141 | W16: =$I16*KYZ_EEIO_2017!CK16 -> 902.15269 | X16: =$I16*KYZ_EEIO_2017!CL16 -> 94.511234 | Z16: =$I16*KYZ_EEIO_2017!CY16 -> 128.44983 | AA16: =$I16*KYZ_EEIO_2017!CZ16 -> 39.609975 | AB16: =$I16*KYZ_EEIO_2017!DA16 -> 0.26535046 | AC16: =$I16*KYZ_EEIO_2017!DB16 -> 0 | AD16: =$I16*KYZ_EEIO_2017!DC16 -> 3.6806685
A17: Rubber and plastics | B17: c10 | D17: 26.775083 | E17: 0 | F17: =D17*(1+E17) -> 26.775083 | H17: 76.339825 | I17: 76.339825 | J17: =IF(H17=0,0,(I17-H17)/H17) -> 0 | L17: 5805.0953 | M17: =SUM(P17:X17) -> 5805.0953 | N17: =M17-L17 -> 0 | P17: =$I17*KYZ_EEIO_2017!CD17 -> 205.92399 | Q17: =$I17*KYZ_EEIO_2017!CE17 -> 831.05038 | R17: =$I17*KYZ_EEIO_2017!CF17 -> 250.05056 | S17: =$I17*KYZ_EEIO_2017!CG17 -> 49.029521 | T17: =$I17*KYZ_EEIO_2017!CH17 -> 615.32049 | U17: =$I17*KYZ_EEIO_2017!CI17 -> 98.059042 | V17: =$I17*KYZ_EEIO_2017!CJ17 -> 1765.0628 | W17: =$I17*KYZ_EEIO_2017!CK17 -> 1801.8349 | X17: =$I17*KYZ_EEIO_2017!CL17 -> 188.76366 | Z17: =$I17*KYZ_EEIO_2017!CY17 -> 6052.6366 | AA17: =$I17*KYZ_EEIO_2017!CZ17 -> 89.757302 | AB17: =$I17*KYZ_EEIO_2017!DA17 -> 0.47699451 | AC17: =$I17*KYZ_EEIO_2017!DB17 -> 0 | AD17: =$I17*KYZ_EEIO_2017!DC17 -> 6.6163769
A18: Other nonmetallic minerals | B18: c11 | D18: 106.14314 | E18: 0 | F18: =D18*(1+E18) -> 106.14314 | H18: 280.28864 | I18: 280.28864 | J18: =IF(H18=0,0,(I18-H18)/H18) -> 0 | L18: 21313.938 | M18: =SUM(P18:X18) -> 21313.938 | N18: =M18-L18 -> 0 | P18: =$I18*KYZ_EEIO_2017!CD18 -> 756.06873 | Q18: =$I18*KYZ_EEIO_2017!CE18 -> 3051.2774 | R18: =$I18*KYZ_EEIO_2017!CF18 -> 918.08346 | S18: =$I18*KYZ_EEIO_2017!CG18 -> 180.01636 | T18: =$I18*KYZ_EEIO_2017!CH18 -> 2259.2054 | U18: =$I18*KYZ_EEIO_2017!CI18 -> 360.03273 | V18: =$I18*KYZ_EEIO_2017!CJ18 -> 6480.5891 | W18: =$I18*KYZ_EEIO_2017!CK18 -> 6615.6014 | X18: =$I18*KYZ_EEIO_2017!CL18 -> 693.063 | Z18: =$I18*KYZ_EEIO_2017!CY18 -> 436.36594 | AA18: =$I18*KYZ_EEIO_2017!CZ18 -> 351.34226 | AB18: =$I18*KYZ_EEIO_2017!DA18 -> 0.80348773 | AC18: =$I18*KYZ_EEIO_2017!DB18 -> 0 | AD18: =$I18*KYZ_EEIO_2017!DC18 -> 11.145155
A19: Basic metals and fabricated metal | B19: c12 | D19: 983.22603 | E19: 0 | F19: =D19*(1+E19) -> 983.22603 | H19: 1728.3904 | I19: 1728.3904 | J19: =IF(H19=0,0,(I19-H19)/H19) -> 0 | L19: 142341.87 | M19: =SUM(P19:X19) -> 142341.87 | N19: =M19-L19 -> 0 | P19: =$I19*KYZ_EEIO_2017!CD19 -> 5049.2891 | Q19: =$I19*KYZ_EEIO_2017!CE19 -> 20377.488 | R19: =$I19*KYZ_EEIO_2017!CF19 -> 6131.2797 | S19: =$I19*KYZ_EEIO_2017!CG19 -> 1202.2117 | T19: =$I19*KYZ_EEIO_2017!CH19 -> 15087.757 | U19: =$I19*KYZ_EEIO_2017!CI19 -> 2404.4234 | V19: =$I19*KYZ_EEIO_2017!CJ19 -> 43279.621 | W19: =$I19*KYZ_EEIO_2017!CK19 -> 44181.28 | X19: =$I19*KYZ_EEIO_2017!CL19 -> 4628.515 | Z19: =$I19*KYZ_EEIO_2017!CY19 -> 1297.7736 | AA19: =$I19*KYZ_EEIO_2017!CZ19 -> 2080.1698 | AB19: =$I19*KYZ_EEIO_2017!DA19 -> 1.3834284 | AC19: =$I19*KYZ_EEIO_2017!DB19 -> 0 | AD19: =$I19*KYZ_EEIO_2017!DC19 -> 19.189494
A20: Machinery, nec | B20: c13 | D20: 17.612922 | E20: 0 | F20: =D20*(1+E20) -> 17.612922 | H20: 34.198262 | I20: 34.198262 | J20: =IF(H20=0,0,(I20-H20)/H20) -> 0 | L20: 3292.1999 | M20: =SUM(P20:X20) -> 3292.1999 | N20: =M20-L20 -> 0 | P20: =$I20*KYZ_EEIO_2017!CD20 -> 116.78412 | Q20: =$I20*KYZ_EEIO_2017!CE20 -> 471.30734 | R20: =$I20*KYZ_EEIO_2017!CF20 -> 141.80929 | S20: =$I20*KYZ_EEIO_2017!CG20 -> 27.805743 | T20: =$I20*KYZ_EEIO_2017!CH20 -> 348.96207 | U20: =$I20*KYZ_EEIO_2017!CI20 -> 55.611485 | V20: =$I20*KYZ_EEIO_2017!CJ20 -> 1001.0067 | W20: =$I20*KYZ_EEIO_2017!CK20 -> 1021.861 | X20: =$I20*KYZ_EEIO_2017!CL20 -> 107.05211 | Z20: =$I20*KYZ_EEIO_2017!CY20 -> 4162.2653 | AA20: =$I20*KYZ_EEIO_2017!CZ20 -> 42.037746 | AB20: =$I20*KYZ_EEIO_2017!DA20 -> 0.046555572 | AC20: =$I20*KYZ_EEIO_2017!DB20 -> 0 | AD20: =$I20*KYZ_EEIO_2017!DC20 -> 0.64577097
... A41: Other community, social, and personal services | B41: c34 | D41: 171.62248 | E41: 0 | F41: =D41*(1+E41) -> 171.62248 | H41: 229.81577 | I41: 229.81577 | J41: =IF(H41=0,0,(I41-H41)/H41) -> 0 | L41: 71200 | M41: =SUM(P41:X41) -> 71200 | N41: =M41-L41 -> 0 | P41: =$I41*KYZ_EEIO_2017!CD41 -> 5400 | Q41: =$I41*KYZ_EEIO_2017!CE41 -> 8200 | R41: =$I41*KYZ_EEIO_2017!CF41 -> 3800 | S41: =$I41*KYZ_EEIO_2017!CG41 -> 2900 | T41: =$I41*KYZ_EEIO_2017!CH41 -> 5100 | U41: =$I41*KYZ_EEIO_2017!CI41 -> 1800 | V41: =$I41*KYZ_EEIO_2017!CJ41 -> 8300 | W41: =$I41*KYZ_EEIO_2017!CK41 -> 30900 | X41: =$I41*KYZ_EEIO_2017!CL41 -> 4800 | Z41: =$I41*KYZ_EEIO_2017!CY41 -> 481.27813 | AA41: =$I41*KYZ_EEIO_2017!CZ41 -> 100.88187 | AB41: =$I41*KYZ_EEIO_2017!DA41 -> 1.0234676 | AC41: =$I41*KYZ_EEIO_2017!DB41 -> 0 | AD41: =$I41*KYZ_EEIO_2017!DC41 -> 14.19649
A42: Total | D42: =SUM(D8:D41) -> 9443.3367 | E42: =AVERAGE(E8:E41) -> 0 | F42: =SUM(F8:F41) -> 9443.3367 | H42: =SUM(H8:H41) -> 16084.194 | I42: =SUM(I8:I41) -> 16084.194 | J42: =AVERAGE(J8:J41) -> -1.2297191e-16 | L42: =SUM(L8:L41) -> 2351200 | M42: =SUM(M8:M41) -> 2351200 | N42: =M42-L42 -> 0 | P42: =SUM(P8:P41) -> 184800 | Q42: =SUM(Q8:Q41) -> 380100 | R42: =SUM(R8:R41) -> 158200 | S42: =SUM(S8:S41) -> 87700 | T42: =SUM(T8:T41) -> 537300 | U42: =SUM(U8:U41) -> 111300 | V42: =SUM(V8:V41) -> 333800 | W42: =SUM(W8:W41) -> 456500 | X42: =SUM(X8:X41) -> 101500 | Z42: =SUM(Z8:Z41) -> 846641.5 | AA42: =SUM(AA8:AA41) -> 23187.083 | AB42: =SUM(AB8:AB41) -> 7136.9483 | AC42: =SUM(AC8:AC41) -> 11933.122 | AD42: =SUM(AD8:AD41) -> 698.16202

Sheet KYZ_EEIO_2017
A1: Input-Output Table for 2017 | B1: Kyrgyz Republic Input-Output Table, 2017
B2: (current prices, $ million)
A3: in current prices | BB3: Regional disaggregation of value added | BO3: Employment | CB3: Employment/Output Coefficients | CO3: Environmental Factors | CW3: Environmental Factors by unit of output
A4: (industry-by-industry) | D4: AtB | E4: C | F4: 15t16 | G4: 17t18 | H4: 19 | I4: 20 | J4: 21t22 | K4: 23 | L4: 24 | M4: 25 | N4: 26 | O4: 27t28 | P4: 29 | Q4: 30t33 | R4: 34t35 | S4: 36t37 | T4: E | U4: F | V4: 50 | W4: 51 | X4: 52 | Y4: H | Z4: 60 | AA4: 61 | AB4: 62 | AC4: 63 | AD4: 64 | AE4: J | AF4: 70 | AG4: 71t74 | AH4: L | AI4: M | AJ4: N | AK4: O
A5: (millions of US$) | B5: Industry | D5: Agriculture, Hunting, Forestry, and Fishing | E5: Mining and Quarrying | F5: Food, Beverages, and Tobacco | G5: Textiles and Textile Products | H5: Leather, Leather Products, and Footwear | I5: Wood and Products of Wood and Cork | J5: Pulp, Paper, Paper Products, Printing, and Publishing | K5: Coke, Refined Petroleum, and Nuclear Fuel | L5: Chemicals and Chemical Products | M5: Rubber and Plastics | N5: Other Nonmetallic Minerals | O5: Basic Metals and Fabricated Metal | P5: Machinery, nec | Q5: Electrical and Optical Equipment | R5: Transport Equipment | S5: Manufacturing, nec; Recycling | T5: Electricity, Gas, and Water Supply | U5: Construction | V5: Sale, Maintenance, and Repair of Motor Vehicles and Motorcycles; Retail Sale of Fuel | W5: Wholesale Trade and Commission Trade, Except of Motor Vehicles and Motorcycles | X5: Retail Trade, Except of Motor Vehicles and Motorcycles; Repair of Household Goods | Y5: Hotels and Restaurants | Z5: Inland Transport | AA5: Water Transport | AB5: Air Transport | AC5: Other Supporting and Auxiliary Transport Activities; Activities of Travel Agencies | AD5: Post and Telecommunications | AE5: Financial Intermediation | AF5: Real Estate Activities | AG5: Renting of M&Eq and Other Business Activities | AH5: Public Administration and Defense; Compulsory Social Security | AI5: Education | AJ5: Health and Social Work | AK5: Other Community, Social, and Personal Services | AL5: Final Consumption Expenditure by Households | AM5: Final Consumption Expenditure by NPISHs | AN5: Final Consumption Expenditure by Government | AO5: Gross Fixed Capital Formation | AP5: Changes in Inventories and Valuables | AQ5: Exports | AR5: Total Output | AT5: Total Final Demand | AV5: Modeled Output (test) | AW5: Calibration | AY5: Value Added | AZ5: Value Added Coefficient | BD5: Batken oblast | BE5: Djalal-Abad | BF5: Issyk-Kul | BG5: Naryn oblast | BH5: Osh oblast | BI5: Talas oblast | BJ5: Chui oblast | BK5: Bishkek city | BL5: Osh city | BM5: Total | BQ5: Batken oblast | BR5: Djalal-Abad | BS5: Issyk-Kul | BT5: Naryn oblast | BU5: Osh oblast | BV5: Talas oblast | BW5: Chui oblast | BX5: Bishkek city | BY5: Osh city | BZ5: Total | CD5: Batken oblast | CE5: Djalal-Abad | CF5: Issyk-Kul | CG5: Naryn oblast | CH5: Osh oblast | CI5: Talas oblast | CJ5: Chui oblast | CK5: Bishkek city | CL5: Osh city | CM5: Total | CQ5: Energy Usage (TJ) | CR5: Total CO2 emissions (Gg) from EDGAR | CS5: WFN: Total water footprint (Mm3/yr) - Blue | CT5: WFN: Total water footprint (Mm3/yr) - Green | CU5: WFN: Total water footprint (Mm3/yr) - Grey | CY5: Energy Usage (TJ) | CZ5: Total CO2 emissions (Gg) from EDGAR | DA5: WFN: Total water footprint (Mm3/yr) - Blue | DB5: WFN: Total water footprint (Mm3/yr) - Green | DC5: WFN: Total water footprint (Mm3/yr) - Grey
D6: c1 | E6: c2 | F6: c3 | G6: c4 | H6: c5 | I6: c6 | J6: c7 | K6: c8 | L6: c9 | M6: c10 | N6: c11 | O6: c12 | P6: c13 | Q6: c14 | R6: c15 | S6: c16 | T6: c17 | U6: c18 | V6: c19 | W6: c20 | X6: c21 | Y6: c22 | Z6: c23 | AA6: c24 | AB6: c25 | AC6: c26 | AD6: c27 | AE6: c28 | AF6: c29 | AG6: c30 | AH6: c31 | AI6: c32 | AJ6: c33 | AK6: c34 | AL6: c36 | AM6: c37 | AN6: c38 | AO6: c39 | AP6: c40 | AQ6: c41
B7: Domestic
A8: AtB | B8: Agriculture, hunting, forestry, and fishing | C8: c1 | D8: 1378.3353 | E8: 0.32228241 | F8: 115.25778 | G8: 17.084252 | H8: 1.6513547 | I8: 0.008947298 | J8: 0.076101759 | K8: 0.2438327 | L8: 0.11898101 | M8: 0.055009628 | N8: 0.20030818 | O8: 0.045141771 | P8: 0 | Q8: 0 | R8: 0 | S8: 0 | T8: 0 | U8: 0.1738221 | V8: 0 | W8: 0.97974936 | X8: 0.13626731 | Y8: 12.342067 | Z8: 0 | AA8: 0 | AB8: 0 | AC8: 0 | AD8: 0 | AE8: 0 | AF8: 0.27517008 | AG8: 0.21189528 | AH8: 20.888329 | AI8: 10.639964 | AJ8: 11.998817 | AK8: 0.071295647 | AL8: 1088.3774 | AM8: 0.075040674 | AN8: 10.112054 | AO8: 10.78594 | AP8: -6.4143727 | AQ8: 380.41525 | AR8: 3054.468 | AT8: 1483.3513 | AV8: {=MMULT(D265:AK298,AT8:AT41)} -> 3054.468 | AW8: =AV8-AR8 -> 0 | AY8: 908.06214 | AZ8: =AY8/$AR8 -> 0.29728979 | BB8: c1 | BC8: Agriculture | BD8: =$AY8*BQ8/$BZ8 -> 87.887802 | BE8: =$AY8*BR8/$BZ8 -> 209.99147 | BF8: =$AY8*BS8/$BZ8 -> 70.947596 | BG8: =$AY8*BT8/$BZ8 -> 68.767174 | BH8: =$AY8*BU8/$BZ8 -> 294.52477 | BI8: =$AY8*BV8/$BZ8 -> 97.951291 | BJ8: =$AY8*BW8/$BZ8 -> 70.612146 | BK8: =$AY8*BX8/$BZ8 -> 5.367194 | BL8: =$AY8*BY8/$BZ8 -> 2.0126978 | BM8: =SUM(BD8:BL8) -> 908.06214 | BO8: c1 | BP8: Agriculture, hunting, forestry, and fishing | BQ8: 52400 | BR8: 125200 | BS8: 42300 | BT8: 41000 | BU8: 175600 | BV8: 58400 | BW8: 42100 | BX8: 3200 | BY8: 1200 | BZ8: 541400 | CB8: c1 | CC8: Agriculture, hunting, forestry, and fishing | CD8: =BQ8/$AR8 -> 17.155197 | CE8: =BR8/$AR8 -> 40.989135 | CF8: =BS8/$AR8 -> 13.848566 | CG8: =BT8/$AR8 -> 13.42296 | CH8: =BU8/$AR8 -> 57.489553 | CI8: =BV8/$AR8 -> 19.119533 | CJ8: =BW8/$AR8 -> 13.783088 | CK8: =BX8/$AR8 -> 1.0476456 | ... CM8: =BZ8/$AR8 -> 177.24854 | CO8: 1 | CP8: Agriculture, Hunting, Forestry, and Fishing | CQ8: 1912.0999 | CR8: 1350.7742 | CS8: 7117.8215 | CT8: 11933.122 | CU8: 432.85533 | CW8: 1 | CX8: Agriculture, Hunting, Forestry, and Fishing | CY8: =CQ8/$AR8 -> 0.62600097 | CZ8: =CR8/$AR8 -> 0.44222896 | DA8: =CS8/$AR8 -> 2.3302983 | DB8: =CT8/$AR8 -> 3.9067759 | DC8: =CU8/$AR8 -> 0.14171219
A9: C | B9: Mining and quarrying | C9: c2 | D9: 0.0028508189 | E9: 4.6143258 | F9: 2.8864094 | G9: 0.30416723 | H9: 0.032104905 | I9: 0.0028554454 | J9: 0.023218348 | K9: 8.3909665 | L9: 3.8761458 | M9: 1.882613 | N9: 6.8552143 | O9: 13.959651 | P9: 0.98480748 | Q9: 0.22346957 | R9: 0.56805703 | S9: 0.97188221 | T9: 22.130386 | U9: 13.959292 | V9: 0.22576287 | W9: 0.09627378 | X9: 0.45871501 | Y9: 0.17408476 | Z9: 0.66830111 | AA9: 0.0064488929 | AB9: 0.034474038 | AC9: 0.20273007 | AD9: 0.5113689 | AE9: 0 | AF9: 0.010026945 | AG9: 0.0077212692 | AH9: 1.701523 | AI9: 5.763147 | AJ9: 0.042799537 | AK9: 0.14884766 | AL9: 25.268908 | AM9: 0 | AN9: 0 | AO9: 3.7043922 | AP9: -0.39176031 | AQ9: 25.120691 | AR9: 145.42287 | AT9: 53.702231 | AV9: 145.42287 | AW9: =AV9-AR9 -> 0 | AY9: 70.980728 | AZ9: =AY9/$AR9 -> 0.48809879 | BB9: c2 | BC9: Mining and quarrying | BD9: =$AY9*BQ9/$BZ9 -> 23.473942 | BE9: =$AY9*BR9/$BZ9 -> 7.8246472 | BF9: =$AY9*BS9/$BZ9 -> 11.736971 | BG9: =$AY9*BT9/$BZ9 -> 18.443811 | BH9: =$AY9*BU9/$BZ9 -> 0 | BI9: =$AY9*BV9/$BZ9 -> 0.55890337 | BJ9: =$AY9*BW9/$BZ9 -> 8.9424539 | BK9: =$AY9*BX9/$BZ9 -> 0 | BL9: =$AY9*BY9/$BZ9 -> 0 | BM9: =SUM(BD9:BL9) -> 70.980728 | BO9: c2 | BP9: Mining and quarrying | BQ9: 4200 | BR9: 1400 | BS9: 2100 | BT9: 3300 | BU9: 0 | BV9: 100 | BW9: 1600 | BX9: 0 | BY9: 0 | BZ9: 12700 | CB9: c2 | CC9: Mining and quarrying | CD9: =BQ9/$AR9 -> 28.881289 | CE9: =BR9/$AR9 -> 9.6270963 | CF9: =BS9/$AR9 -> 14.440645 | CG9: =BT9/$AR9 -> 22.692441 | CH9: =BU9/$AR9 -> 0 | CI9: =BV9/$AR9 -> 0.68764974 | CJ9: =BW9/$AR9 -> 11.002396 | CK9: =BX9/$AR9 -> 0 | ... CM9: =BZ9/$AR9 -> 87.331517 | CO9: 2 | CP9: Mining and Quarrying | CQ9: 147.72395 | CR9: 181.80787 | CS9: 0.22026195 | CT9: 0 | CU9: 3.055247 | CW9: 2 | CX9: Mining and Quarrying | CY9: =CQ9/$AR9 -> 1.0158234 | CZ9: =CR9/$AR9 -> 1.2502013 | DA9: =CS9/$AR9 -> 0.0015146307 | DB9: =CT9/$AR9 -> 0 | DC9: =CU9/$AR9 -> 0.021009398
A10: 15t16 | B10: Food, beverages, and tobacco | C10: c3 | D10: 7.4546054 | E10: 0.17528078 | F10: 60.077878 | G10: 0.95281997 | H10: 0.10057032 | I10: 0.00046414201 | J10: 0.022884429 | K10: 2.2453305 | L10: 1.0370204 | M10: 0.4874213 | N10: 1.7748616 | O10: 1.3347884 | P10: 0.0036609658 | Q10: 0.00083073543 | R10: 0.0021117197 | S10: 0.0051796772 | T10: 1.3755839 | U10: 33.639682 | V10: 0.0042342592 | W10: 4.5028237 | X10: 56.710564 | Y10: 24.287439 | Z10: 2.9643079 | AA10: 0.028604627 | AB10: 0.15291261 | AC10: 0.89922691 | AD10: 4.0487025 | AE10: 0.30455039 | AF10: 5.2924821 | AG10: 4.0754867 | AH10: 21.267983 | AI10: 10.009758 | AJ10: 6.1944984 | AK10: 2.3336426 | AL10: 322.93788 | AM10: 0.49457835 | AN10: 0 | AO10: 24.004034 | AP10: 16.376746 | AQ10: 25.435918 | AR10: 643.01735 | AT10: 389.24916 | AV10: 643.01735 | AW10: =AV10-AR10 -> 0 | AY10: 174.12816 | AZ10: =AY10/$AR10 -> 0.27079854 | BB10: c3 | BC10: Food, beverages, and tobacco | BD10: =$AY10*BQ10/$BZ10 -> 6.1768434 | BE10: =$AY10*BR10/$BZ10 -> 24.927975 | BF10: =$AY10*BS10/$BZ10 -> 7.5004528 | BG10: =$AY10*BT10/$BZ10 -> 1.470677 | BH10: =$AY10*BU10/$BZ10 -> 18.456996 | BI10: =$AY10*BV10/$BZ10 -> 2.941354 | BJ10: =$AY10*BW10/$BZ10 -> 52.944372 | BK10: =$AY10*BX10/$BZ10 -> 54.04738 | BL10: =$AY10*BY10/$BZ10 -> 5.6621065 | BM10: =SUM(BD10:BL10) -> 174.12816 | BO10: c3 | BP10: Food, beverages, and tobacco | BQ10: 1314.7806 | BR10: 5306.0789 | BS10: 1596.5193 | BT10: 313.043 | BU10: 3928.6897 | BV10: 626.086 | BW10: 11269.548 | BX10: 11504.33 | BY10: 1205.2156 | BZ10: 37064.291 | CB10: c3 | CC10: Food, beverages, and tobacco | CD10: =BQ10/$AR10 -> 2.0447047 | CE10: =BR10/$AR10 -> 8.2518441 | CF10: =BS10/$AR10 -> 2.4828557 | CG10: =BT10/$AR10 -> 0.48683446 | CH10: =BU10/$AR10 -> 6.1097725 | CI10: =BV10/$AR10 -> 0.97366892 | CJ10: =BW10/$AR10 -> 17.526041 | CK10: =BX10/$AR10 -> 17.891166 | ... CM10: =BZ10/$AR10 -> 57.6412 | CO10: 3 | CP10: Food, Beverages, and Tobacco | CQ10: 736.61604 | CR10: 280.60886 | CS10: 1.187814 | CT10: 0 | CU10: 16.476134 | CW10: 3 | CX10: Food, Beverages, and Tobacco | CY10: =CQ10/$AR10 -> 1.1455617 | CZ10: =CR10/$AR10 -> 0.43639393 | DA10: =CS10/$AR10 -> 0.0018472504 | DB10: =CT10/$AR10 -> 0 | DC10: =CU10/$AR10 -> 0.025623156
A11: 17t18 | B11: Textiles and textile products | C11: c4 | D11: 0.0019179564 | E11: 0.035643025 | F11: 0.28227247 | G11: 3.3471472 | H11: 0.37845463 | I11: 0.0065982685 | J11: 0.084192735 | K11: 0.77681805 | L11: 0.35877844 | M11: 0.06761791 | N11: 0.24621909 | O11: 0.2302144 | P11: 0.09999728 | Q11: 0.022691084 | R11: 0.05768047 | S11: 0.24737829 | T11: 0.12832944 | U11: 0.024255061 | V11: 0.0035012439 | W11: 0.026120492 | X11: 0.22132882 | Y11: 0.98336914 | Z11: 0.070045362 | AA11: 0.00067591544 | AB11: 0.0036132613 | AC11: 0.021248358 | AD11: 0.077014289 | AE11: 0.0011700838 | AF11: 0.045537474 | AG11: 0.035066224 | AH11: 0.78931775 | AI11: 0.44280834 | AJ11: 0.56376094 | AK11: 0.39399717 | AL11: 84.96462 | AM11: 0.38056023 | AN11: 0 | AO11: 0.10511489 | AP11: 1.1652032 | AQ11: 31.620554 | AR11: 128.31083 | AT11: 118.23605 | AV11: 128.31083 | AW11: =AV11-AR11 -> 0 | AY11: 41.308522 | AZ11: =AY11/$AR11 -> 0.32194103 | BB11: c4 | BC11: Textile products | BD11: =$AY11*BQ11/$BZ11 -> 1.4653361 | BE11: =$AY11*BR11/$BZ11 -> 5.9136777 | BF11: =$AY11*BS11/$BZ11 -> 1.7793367 | BG11: =$AY11*BT11/$BZ11 -> 0.34888954 | BH11: =$AY11*BU11/$BZ11 -> 4.3785638 | BI11: =$AY11*BV11/$BZ11 -> 0.69777909 | BJ11: =$AY11*BW11/$BZ11 -> 12.560024 | BK11: =$AY11*BX11/$BZ11 -> 12.821691 | BL11: =$AY11*BY11/$BZ11 -> 1.3432247 | BM11: =SUM(BD11:BL11) -> 41.308522 | BO11: c4 | BP11: Textiles and textile products | BQ11: 311.90615 | BR11: 1258.7641 | BS11: 378.74318 | BT11: 74.263369 | BU11: 932.00528 | BV11: 148.52674 | BW11: 2673.4813 | BX11: 2729.1788 | BY11: 285.91397 | BZ11: 8792.7829 | CB11: c4 | CC11: Textiles and textile products | CD11: =BQ11/$AR11 -> 2.4308637 | CE11: =BR11/$AR11 -> 9.8102715 | CF11: =BS11/$AR11 -> 2.9517631 | CG11: =BT11/$AR11 -> 0.57877708 | CH11: =BU11/$AR11 -> 7.2636524 | CI11: =BV11/$AR11 -> 1.1575542 | CJ11: =BW11/$AR11 -> 20.835975 | CK11: =BX11/$AR11 -> 21.270058 | ... CM11: =BZ11/$AR11 -> 68.527206 | CO11: 4 | CP11: Textiles and Textile Products | CQ11: 257.57702 | CR11: 63.024613 | CS11: 0.48447421 | CT11: 0 | CU11: 6.7201275 | CW11: 4 | CX11: Textiles and Textile Products | CY11: =CQ11/$AR11 -> 2.0074456 | CZ11: =CR11/$AR11 -> 0.491187 | DA11: =CS11/$AR11 -> 0.0037757857 | DB11: =CT11/$AR11 -> 0 | DC11: =CU11/$AR11 -> 0.052373813
A12: 19 | B12: Leather, leather products, and footwear | C12: c5 | D12: 0.0002028535 | E12: 0.0037698002 | F12: 0.029854671 | G12: 0.37922646 | H12: 0.04002742 | I12: 0.00069786876 | J12: 0.0089046816 | K12: 0.082160502 | L12: 0.037946359 | M12: 0.007151638 | N12: 0.026041471 | O12: 0.024348727 | P12: 0.010576256 | Q12: 0.0023999325 | R12: 0.0061006002 | S12: 0.026164074 | T12: 0.01357282 | U12: 0.0025653472 | V12: 0.0003703106 | W12: 0.0027626453 | X12: 0.023408939 | Y12: 0.10400647 | Z12: 0.0074083785 | AA12: 7.1488493e-05 | AB12: 0.00038215816 | AC12: 0.0022473419 | AD12: 0.0081454501 | AE12: 0.00012375443 | AF12: 0.0048162909 | AG12: 0.0037087946 | AH12: 0.083482538 | AI12: 0.046833818 | AJ12: 0.059626423 | AK12: 0.041671283 | AL12: 8.9863204 | AM12: 0.04025012 | AN12: 0 | AO12: 0.011117523 | AP12: 0.12326842 | AQ12: 3.3437715 | AR12: 13.595506 | AT12: 12.504728 | AV12: 13.595506 | AW12: =AV12-AR12 -> -5.6843419e-14 | AY12: 4.3769511 | AZ12: =AY12/$AR12 -> 0.32194103 | BB12: c5 | BC12: Leather products & footwear | BD12: =$AY12*BQ12/$BZ12 -> 0.15526347 | BE12: =$AY12*BR12/$BZ12 -> 0.62659899 | BF12: =$AY12*BS12/$BZ12 -> 0.18853421 | BG12: =$AY12*BT12/$BZ12 -> 0.036967492 | BH12: =$AY12*BU12/$BZ12 -> 0.46394203 | BI12: =$AY12*BV12/$BZ12 -> 0.073934984 | BJ12: =$AY12*BW12/$BZ12 -> 1.3308297 | BK12: =$AY12*BX12/$BZ12 -> 1.3585553 | BL12: =$AY12*BY12/$BZ12 -> 0.14232484 | BM12: =SUM(BD12:BL12) -> 4.3769511 | BO12: c5 | BP12: Leather, leather products, and footwear | BQ12: 33.048821 | BR12: 133.3756 | BS12: 40.130712 | BT12: 7.868767 | BU12: 98.753026 | BV12: 15.737534 | BW12: 283.27561 | BX12: 289.17719 | BY12: 30.294753 | BZ12: 931.66201 | CB12: c5 | CC12: Leather, leather products, and footwear | CD12: =BQ12/$AR12 -> 2.4308637 | CE12: =BR12/$AR12 -> 9.8102715 | CF12: =BS12/$AR12 -> 2.9517631 | CG12: =BT12/$AR12 -> 0.57877708 | CH12: =BU12/$AR12 -> 7.2636524 | CI12: =BV12/$AR12 -> 1.1575542 | CJ12: =BW12/$AR12 -> 20.835975 | CK12: =BX12/$AR12 -> 21.270058 | ... CM12: =BZ12/$AR12 -> 68.527206 | CO12: 5 | CP12: Leather, Leather Products, and Footwear | CQ12: 33.107265 | CR12: 6.1392604 | CS12: 0.065430241 | CT12: 0 | CU12: 0.90758096 | CW12: 5 | CX12: Leather, Leather Products, and Footwear | CY12: =CQ12/$AR12 -> 2.4351625 | CZ12: =CR12/$AR12 -> 0.45156544 | DA12: =CS12/$AR12 -> 0.0048126376 | DB12: =CT12/$AR12 -> 0 | DC12: =CU12/$AR12 -> 0.066755955
A13: 20 | B13: Wood and products of wood and cork | C13: c6 | D13: 0.0003851752 | E13: 0.0030833725 | F13: 0.023914115 | G13: 0.00029565573 | H13: 3.1206515e-05 | I13: 0.016626927 | J13: 0.15233446 | K13: 0.013481925 | L13: 0.0062267143 | M13: 0.013500973 | N13: 0.049161491 | O13: 0.072919217 | P13: 0.0065897943 | Q13: 0.0014953364 | R13: 0.0038011277 | S13: 0.099972398 | T13: 0.016183525 | U13: 0.34998044 | V13: 0.0010601191 | W13: 0.045637327 | X13: 0.06188032 | Y13: 0.060578199 | Z13: 0.0073946369 | AA13: 7.1355891e-05 | AB13: 0.00038144931 | AC13: 0.0022431733 | AD13: 0.010550598 | AE13: 4.6996612e-05 | AF13: 0.0065738699 | AG13: 0.0050622219 | AH13: 0.024156231 | AI13: 0.026508898 | AJ13: 0.0027706604 | AK13: 0.044242046 | AL13: 1.8517087 | AM13: 0.00025575996 | AN13: 0 | AO13: 0.0069802045 | AP13: 0.010329341 | AQ13: 0.95137723 | AR13: 3.9497932 | AT13: 2.8206512 | AV13: 3.9497932 | AW13: =AV13-AR13 -> 0 | AY13: 1.6822554 | AZ13: =AY13/$AR13 -> 0.42590974 | BB13: c6 | BC13: Wood products | BD13: =$AY13*BQ13/$BZ13 -> 0.0596746 | BE13: =$AY13*BR13/$BZ13 -> 0.24082964 | BF13: =$AY13*BS13/$BZ13 -> 0.072462014 | BG13: =$AY13*BT13/$BZ13 -> 0.014208238 | BH13: =$AY13*BU13/$BZ13 -> 0.17831339 | BI13: =$AY13*BV13/$BZ13 -> 0.028416476 | BJ13: =$AY13*BW13/$BZ13 -> 0.51149657 | BK13: =$AY13*BX13/$BZ13 -> 0.52215275 | BL13: =$AY13*BY13/$BZ13 -> 0.054701717 | BM13: =SUM(BD13:BL13) -> 1.6822554 | BO13: c6 | BP13: Wood and products of wood and cork | BQ13: 12.70212 | BR13: 51.262127 | BS13: 15.424003 | BT13: 3.0243143 | BU13: 37.955145 | BV13: 6.0486286 | BW13: 108.87531 | BX13: 111.14355 | BY13: 11.64361 | BZ13: 358.07881 | CB13: c6 | CC13: Wood and products of wood and cork | CD13: =BQ13/$AR13 -> 3.215895 | CE13: =BR13/$AR13 -> 12.978433 | CF13: =BS13/$AR13 -> 3.9050153 | CG13: =BT13/$AR13 -> 0.76568928 | CH13: =BU13/$AR13 -> 9.6094005 | CI13: =BV13/$AR13 -> 1.5313786 | CJ13: =BW13/$AR13 -> 27.564814 | CK13: =BX13/$AR13 -> 28.139081 | ... CM13: =BZ13/$AR13 -> 90.657611 | CO13: 6 | CP13: Wood and Products of Wood and Cork | CQ13: 22.713789 | CR13: 1.7543551 | CS13: 0.049561495 | CT13: 0 | CU13: 0.68746605 | CW13: 6 | CX13: Wood and Products of Wood and Cork | CY13: =CQ13/$AR13 -> 5.7506275 | CZ13: =CR13/$AR13 -> 0.44416379 | DA13: =CS13/$AR13 -> 0.012547871 | DB13: =CT13/$AR13 -> 0 | DC13: =CU13/$AR13 -> 0.17405115
A14: 21t22 | B14: Pulp, paper, paper products, printing, and publishing | C14: c7 | D14: 0.011230723 | E14: 0.087607995 | F14: 0.3431279 | G14: 0.023196666 | H14: 0.0024484121 | I14: 0.20582269 | J14: 1.3532635 | K14: 0.18267617 | L14: 0.084370168 | M14: 0.13162048 | N14: 0.47927356 | O14: 0.94402353 | P14: 0.099656615 | Q14: 0.022613781 | R14: 0.057483967 | S14: 0.87684298 | T14: 0.28172083 | U14: 3.0704924 | V14: 0.015453588 | W14: 0.48384833 | X14: 1.2888536 | Y14: 0.73539986 | Z14: 0.074604433 | AA14: 0.00071990902 | AB14: 0.0038484391 | AC14: 0.022631358 | AD14: 0.12696248 | AE14: 0.080066201 | AF14: 0.06541754 | AG14: 0.05037491 | AH14: 0.44159581 | AI14: 0.78944447 | AJ14: 0.12968381 | AK14: 0.55237798 | AL14: 16.282416 | AM14: 0.003945684 | AN14: 0.17572229 | AO14: 0.058627837 | AP14: 0.19917203 | AQ14: 9.6412972 | AR14: 39.479936 | AT14: 26.361181 | AV14: 39.479936 | AW14: =AV14-AR14 -> 0 | AY14: 13.251194 | AZ14: =AY14/$AR14 -> 0.33564375 | BB14: c7 | BC14: Paper products | BD14: =$AY14*BQ14/$BZ14 -> 0.47005924 | BE14: =$AY14*BR14/$BZ14 -> 1.8970248 | BF14: =$AY14*BS14/$BZ14 -> 0.57078622 | BG14: =$AY14*BT14/$BZ14 -> 0.11191887 | BH14: =$AY14*BU14/$BZ14 -> 1.4045818 | BI14: =$AY14*BV14/$BZ14 -> 0.22383773 | BJ14: =$AY14*BW14/$BZ14 -> 4.0290792 | BK14: =$AY14*BX14/$BZ14 -> 4.1130183 | BL14: =$AY14*BY14/$BZ14 -> 0.43088763 | BM14: =SUM(BD14:BL14) -> 13.251194 | BO14: c7 | BP14: Pulp, paper, paper products, printing, and publishing | BQ14: 100.05511 | BR14: 403.79385 | BS14: 121.49549 | BT14: 23.822646 | BU14: 298.97421 | BV14: 47.645292 | BW14: 857.61526 | BX14: 875.48224 | BY14: 91.717187 | BZ14: 2820.6013 | CB14: c7 | CC14: Pulp, paper, paper products, printing, and publishing | CD14: =BQ14/$AR14 -> 2.5343281 | CE14: =BR14/$AR14 -> 10.227824 | CF14: =BS14/$AR14 -> 3.0773985 | CG14: =BT14/$AR14 -> 0.60341146 | CH14: =BU14/$AR14 -> 7.5728139 | CI14: =BV14/$AR14 -> 1.2068229 | CJ14: =BW14/$AR14 -> 21.722813 | CK14: =BX14/$AR14 -> 22.175371 | ... CM14: =BZ14/$AR14 -> 71.443917 | CO14: 7 | CP14: Pulp, Paper, Paper Products, Printing, and Publishing | CQ14: 78.993743 | CR14: 17.757572 | CS14: 0.15893346 | CT14: 0 | CU14: 2.2045613 | CW14: 7 | CX14: Pulp, Paper, Paper Products, Printing, and Publishing | CY14: =CQ14/$AR14 -> 2.0008579 | CZ14: =CR14/$AR14 -> 0.44978727 | DA14: =CS14/$AR14 -> 0.0040256767 | DB14: =CT14/$AR14 -> 0 | DC14: =CU14/$AR14 -> 0.055840043
A15: 23 | B15: Coke, refined petroleum, and nuclear fuel | C15: c8 | D15: 2.2130152 | E15: 0.95280034 | F15: 0.19098439 | G15: 0.14112795 | H15: 0.01489608 | I15: 0.010911788 | J15: 0.16828598 | K15: 0.44978891 | L15: 0.20773792 | M15: 0.045088967 | N15: 0.16418379 | O15: 1.5555215 | P15: 0.12195166 | Q15: 0.027672907 | R15: 0.070344204 | S15: 0.019759601 | T15: 1.6404699 | U15: 8.6613919 | V15: 0.10687937 | W15: 0.94616081 | X15: 6.5938172 | Y15: 0.016129211 | Z15: 5.1022493 | AA15: 0.041192671 | AB15: 0.22020489 | AC15: 1.5196828 | AD15: 2.2148989 | AE15: 0.04700809 | AF15: 0.37705137 | AG15: 0.29034918 | AH15: 0.71652913 | AI15: 0.032257144 | AJ15: 0.40635281 | AK15: 0.19839645 | AL15: 30.250183 | AM15: 0.61423419 | AN15: 0 | AO15: 7.0251813 | AP15: 1.926133 | AQ15: 9.406335 | AR15: 84.707159 | AT15: 49.222067 | AV15: 84.707159 | AW15: =AV15-AR15 -> 0 | AY15: 29.52951 | AZ15: =AY15/$AR15 -> 0.34860701 | BB15: c8 | BC15: Coke, refined petroleum, and nuclear fuel | BD15: =$AY15*BQ15/$BZ15 -> 1.0474995 | BE15: =$AY15*BR15/$BZ15 -> 4.2274087 | BF15: =$AY15*BS15/$BZ15 -> 1.2719637 | BG15: =$AY15*BT15/$BZ15 -> 0.24940464 | BH15: =$AY15*BU15/$BZ15 -> 3.1300283 | BI15: =$AY15*BV15/$BZ15 -> 0.49880929 | BJ15: =$AY15*BW15/$BZ15 -> 8.9785671 | BK15: =$AY15*BX15/$BZ15 -> 9.1656206 | BL15: =$AY15*BY15/$BZ15 -> 0.96020787 | BM15: =SUM(BD15:BL15) -> 29.52951 | BO15: c8 | BP15: Coke, refined petroleum, and nuclear fuel | BQ15: 222.96696 | BR15: 899.83096 | BS15: 270.7456 | BT15: 53.087372 | BU15: 666.24652 | BV15: 106.17474 | BW15: 1911.1454 | BX15: 1950.9609 | BY15: 204.38638 | BZ15: 6285.5449 | CB15: c8 | CC15: Coke, refined petroleum, and nuclear fuel | CD15: =BQ15/$AR15 -> 2.6322092 | CE15: =BR15/$AR15 -> 10.622844 | CF15: =BS15/$AR15 -> 3.196254 | CG15: =BT15/$AR15 -> 0.62671648 | CH15: =BU15/$AR15 -> 7.8652918 | CI15: =BV15/$AR15 -> 1.253433 | CJ15: =BW15/$AR15 -> 22.561793 | CK15: =BX15/$AR15 -> 23.031831 | ... CM15: =BZ15/$AR15 -> 74.203231 | CO15: 8 | CP15: Coke, Refined Petroleum, and Nuclear Fuel | CQ15: 8207.6301 | CR15: 93.403021 | CS15: 0.11881106 | CT15: 0 | CU15: 1.6480247 | CW15: 8 | CX15: Coke, Refined Petroleum, and Nuclear Fuel | CY15: =CQ15/$AR15 -> 96.894173 | CZ15: =CR15/$AR15 -> 1.1026579 | DA15: =CS15/$AR15 -> 0.0014026094 | DB15: =CT15/$AR15 -> 0 | DC15: =CU15/$AR15 -> 0.019455554
A16: 24 | B16: Chemicals and chemical products | C16: c9 | D16: 1.012228 | E16: 0.48455264 | F16: 0.087355813 | G16: 0.064551593 | H16: 0.006813432 | I16: 0.0049910263 | J16: 0.076973613 | K16: 0.2057324 | L16: 0.095018837 | M16: 0.020623588 | N16: 0.075097281 | O16: 0.7114919 | P16: 0.055780405 | Q16: 0.012657523 | R16: 0.032175275 | S16: 0.0090379951 | T16: 0.84134828 | U16: 3.9617004 | V16: 0.05969197 | W16: 0.4931462 | X16: 3.3940046 | Y16: 0.0073774632 | Z16: 2.1860292 | AA16: 0.023746204 | AB16: 0.12694079 | AC16: 0.63534815 | AD16: 1.0130896 | AE16: 0.021501391 | AF16: 0.17246242 | AG16: 0.13280504 | AH16: 0.32773875 | AI16: 0.014754342 | AJ16: 0.18586482 | AK16: 0.090746071 | AL16: 13.836363 | AM16: 0.28094928 | AN16: 0 | AO16: 3.2133015 | AP16: 0.88178625 | AQ16: 4.2921988 | AR16: 39.147976 | AT16: 22.504599 | AV16: 39.147976 | AW16: =AV16-AR16 -> 0 | AY16: 13.654874 | AZ16: =AY16/$AR16 -> 0.34880155 | BB16: c9 | BC16: Chemical products | BD16: =$AY16*BQ16/$BZ16 -> 0.48437899 | BE16: =$AY16*BR16/$BZ16 -> 1.9548152 | BF16: =$AY16*BS16/$BZ16 -> 0.58817449 | BG16: =$AY16*BT16/$BZ16 -> 0.11532833 | BH16: =$AY16*BU16/$BZ16 -> 1.4473706 | BI16: =$AY16*BV16/$BZ16 -> 0.23065666 | BJ16: =$AY16*BW16/$BZ16 -> 4.1518199 | BK16: =$AY16*BX16/$BZ16 -> 4.2383162 | BL16: =$AY16*BY16/$BZ16 -> 0.44401408 | BM16: =SUM(BD16:BL16) -> 13.654874 | BO16: c9 | BP16: Chemicals and chemical products | BQ16: 103.10316 | BR16: 416.09491 | BS16: 125.1967 | BT16: 24.548372 | BU16: 308.08207 | BV16: 49.096745 | BW16: 883.74141 | BX16: 902.15269 | BY16: 94.511234 | BZ16: 2906.5273 | CB16: c9 | CC16: Chemicals and chemical products | CD16: =BQ16/$AR16 -> 2.6336781 | CE16: =BR16/$AR16 -> 10.628772 | CF16: =BS16/$AR16 -> 3.1980376 | CG16: =BT16/$AR16 -> 0.6270662 | CH16: =BU16/$AR16 -> 7.8696808 | CI16: =BV16/$AR16 -> 1.2541324 | CJ16: =BW16/$AR16 -> 22.574383 | CK16: =BX16/$AR16 -> 23.044683 | ... CM16: =BZ16/$AR16 -> 74.244638 | CO16: 9 | CP16: Chemicals and Chemical Products | CQ16: 128.44983 | CR16: 39.609975 | CS16: 0.26535046 | CT16: 0 | CU16: 3.6806685 | CW16: 9 | CX16: Chemicals and Chemical Products | CY16: =CQ16/$AR16 -> 3.2811359 | CZ16: =CR16/$AR16 -> 1.0118014 | DA16: =CS16/$AR16 -> 0.00677814 | DB16: =CT16/$AR16 -> 0 | DC16: =CU16/$AR16 -> 0.094019382
A17: 25 | B17: Rubber and plastics | C17: c10 | D17: 0.10100093 | E17: 0.01321659 | F17: 0.78944415 | G17: 0.036063585 | H17: 0.0038065178 | I17: 0.00016242853 | J17: 0.0034703842 | K17: 0.016133593 | L17: 0.007451404 | M17: 2.1045083 | N17: 7.6632084 | O17: 0.043316434 | P17: 0.067143821 | Q17: 0.015236075 | R17: 0.038729925 | S17: 0.01043199 | T17: 0.78056237 | U17: 28.221606 | V17: 0.00014112358 | W17: 1.1601364 | X17: 4.4560687 | Y17: 0.4281154 | Z17: 1.1252652 | AA17: 0.01085845 | AB17: 0.058046341 | AC17: 0.34135074 | AD17: 0.69847301 | AE17: 0.0012262176 | AF17: 0.6578214 | AG17: 0.50655671 | AH17: 0.041606396 | AI17: 0.055534743 | AJ17: 0.0077454652 | AK17: 0.10030262 | AL17: 13.113181 | AM17: 0.012706102 | AN17: 0 | AO17: 3.3823209 | AP17: 0.99270697 | AQ17: 9.2741681 | AR17: 76.339825 | AT17: 26.775083 | AV17: 76.339825 | AW17: =AV17-AR17 -> 0 | AY17: 27.272356 | AZ17: =AY17/$AR17 -> 0.35724939 | BB17: c10 | BC17: Rubber and plastics | BD17: =$AY17*BQ17/$BZ17 -> 0.96743154 | BE17: =$AY17*BR17/$BZ17 -> 3.9042773 | BF17: =$AY17*BS17/$BZ17 -> 1.1747383 | BG17: =$AY17*BT17/$BZ17 -> 0.23034084 | BH17: =$AY17*BU17/$BZ17 -> 2.8907776 | BI17: =$AY17*BV17/$BZ17 -> 0.46068169 | BJ17: =$AY17*BW17/$BZ17 -> 8.2922704 | BK17: =$AY17*BX17/$BZ17 -> 8.465026 | BL17: =$AY17*BY17/$BZ17 -> 0.88681225 | BM17: =SUM(BD17:BL17) -> 27.272356 | BO17: c10 | BP17: Rubber and plastics | BQ17: 205.92399 | BR17: 831.05038 | BS17: 250.05056 | BT17: 49.029521 | BU17: 615.32049 | BV17: 98.059042 | BW17: 1765.0628 | BX17: 1801.8349 | BY17: 188.76366 | BZ17: 5805.0953 | CB17: c10 | CC17: Rubber and plastics | CD17: =BQ17/$AR17 -> 2.6974647 | CE17: =BR17/$AR17 -> 10.886197 | CF17: =BS17/$AR17 -> 3.2754929 | CG17: =BT17/$AR17 -> 0.64225351 | CH17: =BU17/$AR17 -> 8.0602816 | CI17: =BV17/$AR17 -> 1.284507 | CJ17: =BW17/$AR17 -> 23.121126 | CK17: =BX17/$AR17 -> 23.602817 | ... CM17: =BZ17/$AR17 -> 76.042816 | CO17: 10 | CP17: Rubber and Plastics | CQ17: 6052.6366 | CR17: 89.757302 | CS17: 0.47699451 | CT17: 0 | CU17: 6.6163769 | CW17: 10 | CX17: Rubber and Plastics | CY17: =CQ17/$AR17 -> 79.285439 | CZ17: =CR17/$AR17 -> 1.1757599 | DA17: =CS17/$AR17 -> 0.006248305 | DB17: =CT17/$AR17 -> 0 | DC17: =CU17/$AR17 -> 0.086670056
A18: 26 | B18: Other nonmetallic minerals | C18: c11 | D18: 0.38473113 | E18: 0.050344426 | F18: 3.0071382 | G18: 0.13737284 | H18: 0.014499727 | I18: 0.0006187202 | J18: 0.013219333 | K18: 0.061455826 | L18: 0.028383771 | M18: 6.6776852 | N18: 26.753112 | O18: 0.16500027 | P18: 0.25576318 | Q18: 0.058037017 | R18: 0.14752942 | S18: 0.039737372 | T18: 2.9733059 | U18: 96.621799 | V18: 0.0005375657 | W18: 4.4191732 | X18: 16.973987 | Y18: 1.6307704 | Z18: 4.2863423 | AA18: 0.041361838 | AB18: 0.22110921 | AC18: 1.3002679 | AD18: 2.6606124 | AE18: 0.0046708886 | AF18: 2.5057629 | AG18: 1.9295678 | AH18: 0.15848642 | AI18: 0.21154207 | AJ18: 0.029503904 | AK18: 0.38207114 | AL18: 49.950522 | AM18: 0.048399885 | AN18: 0 | AO18: 12.883883 | AP18: 3.7562968 | AQ18: 39.50404 | AR18: 280.28864 | AT18: 106.14314 | AV18: 280.28864 | AW18: =AV18-AR18 -> 0 | AY18: 100.13295 | AZ18: =AY18/$AR18 -> 0.35724939 | BB18: c11 | BC18: Other nonmetallic minerals | BD18: =$AY18*BQ18/$BZ18 -> 3.5520133 | BE18: =$AY18*BR18/$BZ18 -> 14.334911 | BF18: =$AY18*BS18/$BZ18 -> 4.313159 | BG18: =$AY18*BT18/$BZ18 -> 0.84571745 | BH18: =$AY18*BU18/$BZ18 -> 10.613754 | BI18: =$AY18*BV18/$BZ18 -> 1.6914349 | BJ18: =$AY18*BW18/$BZ18 -> 30.445828 | BK18: =$AY18*BX18/$BZ18 -> 31.080116 | BL18: =$AY18*BY18/$BZ18 -> 3.2560122 | BM18: =SUM(BD18:BL18) -> 100.13295 | BO18: c11 | BP18: Other nonmetallic minerals | BQ18: 756.06873 | BR18: 3051.2774 | BS18: 918.08346 | BT18: 180.01636 | BU18: 2259.2054 | BV18: 360.03273 | BW18: 6480.5891 | BX18: 6615.6014 | BY18: 693.063 | BZ18: 21313.938 | CB18: c11 | CC18: Other nonmetallic minerals | CD18: =BQ18/$AR18 -> 2.6974647 | CE18: =BR18/$AR18 -> 10.886197 | CF18: =BS18/$AR18 -> 3.2754929 | CG18: =BT18/$AR18 -> 0.64225351 | CH18: =BU18/$AR18 -> 8.0602816 | CI18: =BV18/$AR18 -> 1.284507 | CJ18: =BW18/$AR18 -> 23.121126 | CK18: =BX18/$AR18 -> 23.602817 | ... CM18: =BZ18/$AR18 -> 76.042816 | CO18: 11 | CP18: Other Nonmetallic Minerals | CQ18: 436.36594 | CR18: 351.34226 | CS18: 0.80348773 | CT18: 0 | CU18: 11.145155 | CW18: 11 | CX18: Other Nonmetallic Minerals | CY18: =CQ18/$AR18 -> 1.5568449 | CZ18: =CR18/$AR18 -> 1.2535016 | DA18: =CS18/$AR18 -> 0.0028666439 | DB18: =CT18/$AR18 -> 0 | DC18: =CU18/$AR18 -> 0.039763134
A19: 27t28 | B19: Basic metals and fabricated metal | C19: c12 | D19: 5.3915921 | E19: 0.86736334 | F19: 1.0242407 | G19: 0.7388868 | H19: 0.077989632 | I19: 0.010170561 | J19: 0.21518996 | K19: 0.31077493 | L19: 0.14353341 | M19: 1.1610611 | N19: 4.2278059 | O19: 680.66175 | P19: 1.3994914 | Q19: 0.3175684 | R19: 0.80725516 | S19: 0.54063281 | T19: 3.5194957 | U19: 39.760639 | V19: 0.040742772 | W19: 0.46117166 | X19: 1.0820738 | Y19: 0.16646097 | Z19: 0.29113884 | AA19: 0.0028093971 | AB19: 0.015018278 | AC19: 0.088317371 | AD19: 0.68821235 | AE19: 0.0096207525 | AF19: 0.19080627 | AG19: 0.14693076 | AH19: 0.021620347 | AI19: 0.14276341 | AJ19: 0.050785418 | AK19: 0.59048227 | AL19: 13.142784 | AM19: 0.0042810917 | AN19: 0 | AO19: 0.36787173 | AP19: 8.9889044 | AQ19: 960.72219 | AR19: 1728.3904 | AT19: 983.22603 | AV19: 1728.3904 | AW19: =AV19-AR19 -> 0 | AY19: 668.72253 | AZ19: =AY19/$AR19 -> 0.38690479 | BB19: c12 | BC19: Basic metals and fabricated metal | BD19: =$AY19*BQ19/$BZ19 -> 23.721576 | BE19: =$AY19*BR19/$BZ19 -> 95.733504 | BF19: =$AY19*BS19/$BZ19 -> 28.804771 | BG19: =$AY19*BT19/$BZ19 -> 5.6479943 | BH19: =$AY19*BU19/$BZ19 -> 70.882329 | BI19: =$AY19*BV19/$BZ19 -> 11.295989 | BJ19: =$AY19*BW19/$BZ19 -> 203.3278 | BK19: =$AY19*BX19/$BZ19 -> 207.56379 | BL19: =$AY19*BY19/$BZ19 -> 21.744778 | BM19: =SUM(BD19:BL19) -> 668.72253 | BO19: c12 | BP19: Basic metals and fabricated metal | BQ19: 5049.2891 | BR19: 20377.488 | BS19: 6131.2797 | BT19: 1202.2117 | BU19: 15087.757 | BV19: 2404.4234 | BW19: 43279.621 | BX19: 44181.28 | BY19: 4628.515 | BZ19: 142341.87 | CB19: c12 | CC19: Basic metals and fabricated metal | CD19: =BQ19/$AR19 -> 2.9213823 | CE19: =BR19/$AR19 -> 11.789864 | CF19: =BS19/$AR19 -> 3.5473928 | CG19: =BT19/$AR19 -> 0.69556721 | CH19: =BU19/$AR19 -> 8.7293685 | CI19: =BV19/$AR19 -> 1.3911344 | CJ19: =BW19/$AR19 -> 25.04042 | CK19: =BX19/$AR19 -> 25.562095 | ... CM19: =BZ19/$AR19 -> 82.355157 | CO19: 12 | CP19: Basic Metals and Fabricated Metal | CQ19: 1297.7736 | CR19: 2080.1698 | CS19: 1.3834284 | CT19: 0 | CU19: 19.189494 | CW19: 12 | CX19: Basic Metals and Fabricated Metal | CY19: =CQ19/$AR19 -> 0.75085676 | CZ19: =CR19/$AR19 -> 1.2035301 | DA19: =CS19/$AR19 -> 0.00080041428 | DB19: =CT19/$AR19 -> 0 | DC19: =CU19/$AR19 -> 0.011102523
A20: 29 | B20: Machinery, nec | C20: c13 | D20: 2.8659537 | E20: 0.12127128 | F20: 0.14301149 | G20: 0.018525718 | H20: 0.0019553928 | I20: 0.0011933615 | J20: 0.027885612 | K20: 0.033765802 | L20: 0.015594954 | M20: 0.073923135 | N20: 0.26917849 | O20: 0.59948273 | P20: 0.17149107 | Q20: 0.03891424 | R20: 0.098919542 | S20: 0.020215163 | T20: 1.1289642 | U20: 3.5368231 | V20: 0.0079612419 | W20: 0.31620733 | X20: 1.4569704 | Y20: 0.33468868 | Z20: 1.2109127 | AA20: 0.013114207 | AB20: 0.070105008 | AC20: 0.35235485 | AD20: 2.2434052 | AE20: 0.02805891 | AF20: 0.19473144 | AG20: 0.14995334 | AH20: 0.33365425 | AI20: 0.18939591 | AJ20: 0.10855432 | AK20: 0.408204 | AL20: 12.91017 | AM20: 0.037978036 | AN20: 0 | AO20: 0.13540937 | AP20: 0.022426628 | AQ20: 4.506938 | AR20: 34.198262 | AT20: 17.612922 | AV20: 34.198262 | AW20: =AV20-AR20 -> 0 | AY20: 15.466766 | AZ20: =AY20/$AR20 -> 0.45226758 | BB20: c13 | BC20: Machinery, nec | BD20: =$AY20*BQ20/$BZ20 -> 0.54865216 | BE20: =$AY20*BR20/$BZ20 -> 2.2142033 | BF20: =$AY20*BS20/$BZ20 -> 0.66622048 | BG20: =$AY20*BT20/$BZ20 -> 0.13063147 | BH20: =$AY20*BU20/$BZ20 -> 1.6394249 | BI20: =$AY20*BV20/$BZ20 -> 0.26126293 | BJ20: =$AY20*BW20/$BZ20 -> 4.7027328 | BK20: =$AY20*BX20/$BZ20 -> 4.8007064 | BL20: =$AY20*BY20/$BZ20 -> 0.50293114 | BM20: =SUM(BD20:BL20) -> 15.466766 | BO20: c13 | BP20: Machinery, nec | BQ20: 116.78412 | BR20: 471.30734 | BS20: 141.80929 | BT20: 27.805743 | BU20: 348.96207 | BV20: 55.611485 | BW20: 1001.0067 | BX20: 1021.861 | BY20: 107.05211 | BZ20: 3292.1999 | CB20: c13 | CC20: Machinery, nec | CD20: =BQ20/$AR20 -> 3.4149138 | CE20: =BR20/$AR20 -> 13.781616 | CF20: =BS20/$AR20 -> 4.146681 | CG20: =BT20/$AR20 -> 0.81307472 | CH20: =BU20/$AR20 -> 10.204088 | CI20: =BV20/$AR20 -> 1.6261494 | CJ20: =BW20/$AR20 -> 29.27069 | CK20: =BX20/$AR20 -> 29.880496 | ... CM20: =BZ20/$AR20 -> 96.268046 | CO20: 13 | CP20: Machinery, nec | CQ20: 4162.2653 | CR20: 42.037746 | CS20: 0.046555572 | CT20: 0 | CU20: 0.64577097 | CW20: 13 | CX20: Machinery, nec | CY20: =CQ20/$AR20 -> 121.70985 | CZ20: =CR20/$AR20 -> 1.2292363 | DA20: =CS20/$AR20 -> 0.0013613432 | DB20: =CT20/$AR20 -> 0 | DC20: =CU20/$AR20 -> 0.018883151
A21: 30t33 | B21: Electrical and optical equipment | C21: c14 | D21: 0.64764109 | E21: 0.027404581 | F21: 0.03231738 | G21: 0.0041863957 | H21: 0.0004418748 | I21: 0.00026967287 | J21: 0.0063015212 | K21: 0.007630312 | L21: 0.0035241089 | M21: 0.016704966 | N21: 0.060828287 | O21: 0.13546962 | P21: 0.038753125 | Q21: 0.0087937432 | R21: 0.022353592 | S21: 0.0045681724 | T21: 0.27909076 | U21: 0.79924249 | V21: 0.0017990616 | W21: 0.071455746 | X21: 0.32924254 | Y21: 0.075632115 | Z21: 0.30711024 | AA21: 0.002963516 | AB21: 0.015842155 | AC21: 0.093162316 | AD21: 0.54039789 | AE21: 0.0063406828 | AF21: 0.044004926 | AG21: 0.033886083 | AH21: 0.075398358 | AI21: 0.042799217 | AJ21: 0.024530836 | AK21: 0.092244926 | AL21: 2.9176493 | AM21: 0.0085828665 | AN21: 0 | AO21: 0.030601912 | AP21: 0.0050667365 | AQ21: 1.0129548 | AR21: 7.827188 | AT21: 3.9748557 | AV21: 7.827188 | AW21: =AV21-AR21 -> 0 | AY21: 3.5736685 | AZ21: =AY21/$AR21 -> 0.45657119 | BB21: c14 | BC21: Electrical and optical equipment | BD21: =$AY21*BQ21/$BZ21 -> 0.12676865 | BE21: =$AY21*BR21/$BZ21 -> 0.51160204 | BF21: =$AY21*BS21/$BZ21 -> 0.15393336 | BG21: =$AY21*BT21/$BZ21 -> 0.030183011 | BH21: =$AY21*BU21/$BZ21 -> 0.37879679 | BI21: =$AY21*BV21/$BZ21 -> 0.060366022 | BJ21: =$AY21*BW21/$BZ21 -> 1.0865884 | BK21: =$AY21*BX21/$BZ21 -> 1.1092257 | BL21: =$AY21*BY21/$BZ21 -> 0.11620459 | BM21: =SUM(BD21:BL21) -> 3.5736685 | BO21: c14 | BP21: Electrical and optical equipment | BQ21: 26.983517 | BR21: 108.89776 | BS21: 32.765699 | BT21: 6.4246469 | BU21: 80.629318 | BV21: 12.849294 | BW21: 231.28729 | BX21: 236.10577 | BY21: 24.73489 | BZ21: 760.67819 | CB21: c14 | CC21: Electrical and optical equipment | CD21: =BQ21/$AR21 -> 3.4474088 | CE21: =BR21/$AR21 -> 13.912757 | CF21: =BS21/$AR21 -> 4.1861393 | CG21: =BT21/$AR21 -> 0.82081163 | CH21: =BU21/$AR21 -> 10.301186 | CI21: =BV21/$AR21 -> 1.6416233 | CJ21: =BW21/$AR21 -> 29.549219 | CK21: =BX21/$AR21 -> 30.164827 | ... CM21: =BZ21/$AR21 -> 97.184096 | CO21: 14 | CP21: Electrical and Optical Equipment | CQ21: 9.6804775 | CR21: 9.0456519 | CS21: 0.015848715 | CT21: 0 | CU21: 0.21983707 | CW21: 14 | CX21: Electrical and Optical Equipment | CY21: =CQ21/$AR21 -> 1.2367759 | CZ21: =CR21/$AR21 -> 1.1556707 | DA21: =CS21/$AR21 -> 0.0020248288 | DB21: =CT21/$AR21 -> 0 | DC21: =CU21/$AR21 -> 0.02808634
A22: 34t35 | B22: Transport equipment | C22: c15 | D22: 1.6610626 | E22: 0.070286964 | F22: 0.082887256 | G22: 0.010737221 | H22: 0.0011333156 | I22: 0.00069165396 | J22: 0.016162071 | K22: 0.019570139 | L22: 0.0090385951 | M22: 0.042844711 | N22: 0.15601171 | O22: 0.34745096 | P22: 0.099393581 | Q22: 0.022554094 | R22: 0.057332244 | S22: 0.011716397 | T22: 0.71580886 | U22: 2.0498882 | V22: 0.0046142132 | W22: 0.1832689 | X22: 0.8444376 | Y22: 0.1939804 | Z22: 0.78767291 | AA22: 0.0076007927 | AB22: 0.040631784 | AC22: 0.23894167 | AD22: 1.24061 | AE22: 0.016262512 | AF22: 0.11286334 | AG22: 0.086910647 | AH22: 0.19338087 | AI22: 0.10977095 | AJ22: 0.062916414 | AK22: 0.23658876 | AL22: 7.482564 | AM22: 0.022011503 | AN22: 0 | AO22: 0.078481249 | AP22: 0.012949662 | AQ22: 2.6064163 | AR22: 19.937445 | AT22: 10.202423 | AV22: 19.937445 | AW22: =AV22-AR22 -> 0 | AY22: 9.1232064 | AZ22: =AY22/$AR22 -> 0.45759155 | BB22: c15 | BC22: Transport equipment | BD22: =$AY22*BQ22/$BZ22 -> 0.32362725 | BE22: =$AY22*BR22/$BZ22 -> 1.3060671 | BF22: =$AY22*BS22/$BZ22 -> 0.39297595 | BG22: =$AY22*BT22/$BZ22 -> 0.077054108 | BH22: =$AY22*BU22/$BZ22 -> 0.96702906 | BI22: =$AY22*BV22/$BZ22 -> 0.15410822 | BJ22: =$AY22*BW22/$BZ22 -> 2.7739479 | BK22: =$AY22*BX22/$BZ22 -> 2.8317385 | BL22: =$AY22*BY22/$BZ22 -> 0.29665832 | BM22: =SUM(BD22:BL22) -> 9.1232064 | BO22: c15 | BP22: Transport equipment | BQ22: 68.88613 | BR22: 278.00474 | BS22: 83.647443 | BT22: 16.401459 | BU22: 205.83832 | BV22: 32.802919 | BW22: 590.45254 | BX22: 602.75363 | BY22: 63.145619 | BZ22: 1941.9328 | CB22: c15 | CC22: Transport equipment | CD22: =BQ22/$AR22 -> 3.4551132 | CE22: =BR22/$AR22 -> 13.94385 | CF22: =BS22/$AR22 -> 4.1954946 | CG22: =BT22/$AR22 -> 0.822646 | CH22: =BU22/$AR22 -> 10.324207 | CI22: =BV22/$AR22 -> 1.645292 | CJ22: =BW22/$AR22 -> 29.615256 | CK22: =BX22/$AR22 -> 30.23224 | ... CM22: =BZ22/$AR22 -> 97.401286 | CO22: 15 | CP22: Transport Equipment | CQ22: 15.437027 | CR22: 21.672981 | CS22: 0.019811355 | CT22: 0 | CU22: 0.27480272 | CW22: 15 | CX22: Transport Equipment | CY22: =CQ22/$AR22 -> 0.77427307 | CZ22: =CR22/$AR22 -> 1.0870491 | DA22: =CS22/$AR22 -> 0.0009936757 | DB22: =CT22/$AR22 -> 0 | DC22: =CU22/$AR22 -> 0.013783247
A23: 36t37 | B23: Manufacturing, nec; recycling | C23: c16 | D23: 0.0017112077 | E23: 0.0080712653 | F23: 0.30706453 | G23: 3.0423322 | H23: 0.34615032 | I23: 0 | J23: 0.040262542 | K23: 0 | L23: 0 | M23: 0.05850331 | N23: 0.21302983 | O23: 0.10325335 | P23: 0.021236006 | Q23: 0.004818811 | R23: 0.012249361 | S23: 0.70692028 | T23: 0.036661567 | U23: 2.8368506 | V23: 0.0086505854 | W23: 0.25665942 | X23: 0.42610576 | Y23: 0.42437033 | Z23: 0.31384598 | AA23: 0.0030285138 | AB23: 0.016189616 | AC23: 0.095205614 | AD23: 0.30738921 | AE23: 0.013310401 | AF23: 0.097376394 | AG23: 0.07498489 | AH23: 0.054185194 | AI23: 0.24338495 | AJ23: 0.023079637 | AK23: 1.5009901 | AL23: 10.177277 | AM23: 0.040736869 | AN23: 0 | AO23: 0.84144122 | AP23: 3.6331984 | AQ23: 1.8568745 | AR23: 28.1474 | AT23: 16.549528 | AV23: 28.1474 | AW23: =AV23-AR23 -> 0 | AY23: 10.264209 | AZ23: =AY23/$AR23 -> 0.36465921 | BB23: c16 | BC23: Manufacturing, nec; recycling | BD23: =$AY23*BQ23/$BZ23 -> 0.364102 | BE23: =$AY23*BR23/$BZ23 -> 1.4694116 | BF23: =$AY23*BS23/$BZ23 -> 0.44212385 | BG23: =$AY23*BT23/$BZ23 -> 0.086690951 | BH23: =$AY23*BU23/$BZ23 -> 1.0879714 | BI23: =$AY23*BV23/$BZ23 -> 0.1733819 | BJ23: =$AY23*BW23/$BZ23 -> 3.1208742 | BK23: =$AY23*BX23/$BZ23 -> 3.1858925 | BL23: =$AY23*BY23/$BZ23 -> 0.33376016 | BM23: =SUM(BD23:BL23) -> 10.264209 | BO23: c16 | BP23: Manufacturing, nec; recycling | BQ23: 77.501437 | BR23: 312.77366 | BS23: 94.108888 | BT23: 18.452723 | BU23: 231.58168 | BV23: 36.905446 | BW23: 664.29803 | BX23: 678.13757 | BY23: 71.042984 | BZ23: 2184.8024 | CB23: c16 | CC23: Manufacturing, nec; recycling | CD23: =BQ23/$AR23 -> 2.7534137 | CE23: =BR23/$AR23 -> 11.111991 | CF23: =BS23/$AR23 -> 3.343431 | CG23: =BT23/$AR23 -> 0.6555747 | CH23: =BU23/$AR23 -> 8.2274625 | CI23: =BV23/$AR23 -> 1.3111494 | CJ23: =BW23/$AR23 -> 23.600689 | CK23: =BX23/$AR23 -> 24.09237 | ... CM23: =BZ23/$AR23 -> 77.620045 | CO23: 16 | CP23: Manufacturing, nec; Recycling | CQ23: 2873.8377 | CR23: 31.96825 | CS23: 0.070442352 | CT23: 0 | CU23: 0.97710381 | CW23: 16 | CX23: Manufacturing, nec; Recycling | CY23: =CQ23/$AR23 -> 102.09958 | CZ23: =CR23/$AR23 -> 1.1357443 | DA23: =CS23/$AR23 -> 0.0025026238 | DB23: =CT23/$AR23 -> 0 | DC23: =CU23/$AR23 -> 0.034713821
A24: E | B24: Electricity, gas, and water supply | C24: c17 | D24: 0.45508647 | E24: 1.7147421 | F24: 7.3802835 | G24: 1.62566 | H24: 0.1715887 | I24: 0.10168416 | J24: 2.1221881 | K24: 2.3717278 | L24: 1.0953978 | M24: 1.4892664 | N24: 5.4229098 | O24: 9.3004469 | P24: 2.3998646 | Q24: 0.54457009 | R24: 1.3842908 | S24: 0.33339062 | T24: 10.25499 | U24: 14.52273 | V24: 0.10227816 | W24: 2.6427501 | X24: 5.4360366 | Y24: 7.0283699 | Z24: 1.4427623 | AA24: 0.013922196 | AB24: 0.074424299 | AC24: 0.43766393 | AD24: 2.2009126 | AE24: 0.86124928 | AF24: 2.2418582 | AG24: 1.7263474 | AH24: 7.2926161 | AI24: 7.5921529 | AJ24: 6.9421565 | AK24: 2.8603908 | AL24: 55.165759 | AM24: 0.016126186 | AN24: 0.70802153 | AO24: 67.713824 | AP24: -2.9758683 | AQ24: 126.35687 | AR24: 358.57144 | AT24: 246.98473 | AV24: 358.57144 | AW24: =AV24-AR24 -> 0 | AY24: 158.31998 | AZ24: =AY24/$AR24 -> 0.44152981 | BB24: c17 | BC24: Electricity, gas, and water supply | BD24: =$AY24*BQ24/$BZ24 -> 8.9769061 | BE24: =$AY24*BR24/$BZ24 -> 21.218142 | BF24: =$AY24*BS24/$BZ24 -> 9.3849473 | BG24: =$AY24*BT24/$BZ24 -> 5.3045354 | BH24: =$AY24*BU24/$BZ24 -> 35.907625 | BI24: =$AY24*BV24/$BZ24 -> 7.3447414 | BJ24: =$AY24*BW24/$BZ24 -> 24.890512 | BK24: =$AY24*BX24/$BZ24 -> 37.947831 | BL24: =$AY24*BY24/$BZ24 -> 7.3447414 | BM24: =SUM(BD24:BL24) -> 158.31998 | BO24: c17 | BP24: Electricity, gas, and water supply | BQ24: 2200 | BR24: 5200 | BS24: 2300 | BT24: 1300 | BU24: 8800 | BV24: 1800 | BW24: 6100 | BX24: 9300 | BY24: 1800 | BZ24: 38800 | CB24: c17 | CC24: Electricity, gas, and water supply | CD24: =BQ24/$AR24 -> 6.135458 | CE24: =BR24/$AR24 -> 14.501992 | CF24: =BS24/$AR24 -> 6.4143424 | CG24: =BT24/$AR24 -> 3.6254979 | CH24: =BU24/$AR24 -> 24.541832 | CI24: =BV24/$AR24 -> 5.0199202 | CJ24: =BW24/$AR24 -> 17.011952 | CK24: =BX24/$AR24 -> 25.936254 | ... CM24: =BZ24/$AR24 -> 108.20717 | CO24: 17 | CP24: Electricity, Gas, and Water Supply | CQ24: 252288.19 | CR24: 2977.6219 | CS24: 0.68518742 | CT24: 0 | CU24: 9.5042146 | CW24: 17 | CX24: Electricity, Gas, and Water Supply | CY24: =CQ24/$AR24 -> 703.59254 | CZ24: =CR24/$AR24 -> 8.3041247 | DA24: =CS24/$AR24 -> 0.0019108812 | DB24: =CT24/$AR24 -> 0 | DC24: =CU24/$AR24 -> 0.026505777
